Workbook

Sheet Summary
A1: A.T.L.A.S. Build Baseline
A2: Companion to docs/ATLAS_FRAMEWORK_REVIEW.md v0.4.0 (2026-10-17), built from it by scripts/day1/tools/build-baseline-workbook.py (D-27). v0.4.0 records the action register the Principal returned on 2026-10-16, every row approved as recommended (P-10 with the Principal's change: Eleanor's router stays at 4B for classification only, and her own persona work moves to GLM-5.3-Flash; the questions on P-10 and on memory headroom, N-01 and N-03, are answered in the document's 5.3, 4.1 and 4.2): llama.cpp re-pinned to build tag b11474, with the old pin v0.4.1 kept only for the output-parity test V25 (sheet 4); GLM-5.3-Flash UD-IQ4_XS (with its glm5v projector, also the vision engine and the long-document route) and DeepSeek-V4-Flash-0731 UD-Q8_K_XL (Arthur and the Apex) as the Day 1 seats, gpt-oss-120b as the fast utility and fallback floor, the 4B router unchanged; one LLM seat resident at a time; the Engine Arbiter budgeting exact file bytes; the Qwen3 4B embedder and reranker on the CPU, replacing the bge pair before Day 1; the Phase 3 pull cut to about 448 GB; and pyannote community-1 now (C-06). D16 to D27 on sheet 1 record the decisions (D16 to D18 reopen D4, D10 and D12) and C28 to C30 on sheet 2 supersede C23, C25 and C26; R29 to R33 on sheet 3, with R4, R17, R19 and R20 restated, were acknowledged by the Principal on 2026-10-17, the day the Principal also approved the six RAM fixes (S55: an explicit prompt-cache cap on every engine, a 4 GiB /tmp, at most 8 Celery cpu workers, memory caps on Kokoro, speaches and Docling, an order for the out-of-memory killer, and a seat whose start failed stopped before its reservation goes) and confirmed V25's pass marks, with no new version number. The specialist seats (Intern-S1, Ling-3.0-flash-Fin, Baichuan-M3), slot save and restore, swap batching, the speech, image and OCR companions, the Qwen3.8-Flash-Next and Nemotron 3 Super pulls, the drafters and the DeepSeek V4.1 trial are phased after Day 1, each with its to-do; where an approved row leaves an input to the Principal (the decode floors, the context targets, the test sets), its default is built and a to-do raised (sheet 5). Later on 2026-10-17 (S56) the Principal approved the recommendations for those inputs: decode floors at 8k (gpt-oss-120b 25, GLM-5.3-Flash 6, DeepSeek-V4-Flash-0731 4, the router 20 tok/s) with prefill floors and placement checks, the D-16 profile of the phased medical and science seats, no dedicated coder seat (Qwen3-Coder-Next not pulled), EmbeddingGemma 2 dropped, MedGemma 1.5 4B only on conditions, and the designs of the seat test sets and the V4.1 trial set; and recorded a 2,000 Mbps line with the node moving to a cable on its 10 GbE port before Phase 1. What those answers still leave open is on sheet 5. The same day (S57) the Principal's statements were recorded: ATLAS's Australian law is that of the Commonwealth, VIC, NSW and QLD; an Australian Standard's text is held only under the Principal's own licence, otherwise its number, edition and free commentary; the briefs for the seat test sets are collected once ATLAS is live, from real examples; and the MedGemma licence decision is a task for the live ATLAS with the Principal present. Two proposals await the Principal, not decided: the 16 Australian-law tasks spread across the four jurisdictions, and about 10 Australian tax and finance tasks. The uncensored-seat items (D-07, D-08, D-09, D-58, N-10, P-05, P-17, S-05) are unchanged by this revision and remain the Principal's to configure. Until v0.4.0 this workbook was the closed v0.3.5 record of 2026-10-12: Ubuntu Server kept over Fedora 44 KDE Plasma (C27), the crash-kernel memory reclaimed with panic=10 (S48), kexec handover off (S49), the hardware watchdog (S50), torchaudio pinned so Phase 4 stays on ROCm 10.0.0 (S51), every request kept inside its engine's slot with the Phase 3 memory records (S52), and the pruning fixes (S53), with every decision and resolution confirmed and every risk acknowledged. The Day 1 scripts under scripts/day1 never stop on a missing input from the Principal (they ask once, defer, and keep a to-do list). Nothing has been executed.
A4: How to use this workbook
A5: 1. Sheets 1, 2 and 3 are a record of your answers of 2026-09-21, 2026-10-05 (D15: Secure Boot enabled), 2026-10-08 (C27: Ubuntu kept; R22 to R25 acknowledged), 2026-10-13 (R26 to R28 acknowledged), 2026-10-16 (the action register: D16 to D27 and C28 to C30) and 2026-10-17 (R29 to R33 and the restated R4, R17, R19 and R20 acknowledged; later, S56: your answers to the open inputs in D16 to D26, R9 and R20 restated with B-27; S57: in D20, the briefs collected once ATLAS is live). Nothing on them needs you now. Sheet 5 records the Secure Boot BIOS setting made and the USB recovery drive in hand (both confirmed 2026-10-13) and lists the optional items the scripts ask for at a prompt and the inputs still left to you, each with the default already built. Sheet 4 fills during Day 1.
A6: 2. Use the dropdown in each response column. Cells colour green, amber, or red as you answer.
A7: 3. Where you choose 'Change' or 'Disagree', write the alternative in the next column so it can be folded back into the brief.
A8: 4. Sheet 4 (Verification) is filled during Day 1 as each phase gate runs, not now; its Result column shows amber 'Not yet run' until then.
A9: 5. The Ref sheets carry the agreed maps (hardware, platform watch-list and memory budget, the Day 1 and phased engines, cabinet, domains, task forces, integrations, voice, multimodal, governance, Day 1 and its test plan) for checking against.
A10: 6. Outstanding before Phase 1: sheet 5 row 32, the cable (your choice of 2026-10-17, S56): plug it into the 10 GbE port not marked DASH and a 2.5 GbE router port, move the reservation and the UDP 51820 forward to that port's MAC and take Wi-Fi off the LAN subnet (pre-flight warns, never stops, if it is not done). The other blank sheet 5 rows are optional or wait until after Day 1, and can be given at the prompt or left for the live ATLAS; sheet 5 row 29 still asks you to confirm that the installer's encryption option was taken (if it was not, Day 1 warns and records a to-do, never a stop). To reopen any other item, change its response cell (Changed my mind, Disagree, Discuss or No) and write the reason beside it; the progress table below shows it at once.
A12: Legend
A13: Yellow fill | B13: Cell for you to fill in
A14: Green | B14: Confirmed / Accept / Yes / N/A / Pass
A15: Amber | B15: Deferred / Not yet run (Not yet run counts as Remaining, not Hold)
A16: Red | B16: Changed my mind / Disagree - return to decisions / Discuss / No / Fail
A19: Progress (formulas update as you answer)
A20: Sheet | B20: Items | C20: Answered | D20: Positive | E20: Hold | F20: Negative | G20: Remaining
A21: 1 Decisions | B21: =COUNTA('1 Decisions'!$A$5:$A$31) | C21: =B21-G21 | D21: =COUNTIF('1 Decisions'!$E$5:$E$31,"Confirmed") | E21: =0 | F21: =COUNTIF('1 Decisions'!$E$5:$E$31,"Changed my mind") | G21: =COUNTBLANK('1 Decisions'!$E$5:$E$31)
A22: 2 Resolutions | B22: =COUNTA('2 Resolutions'!$A$5:$A$34) | C22: =B22-G22 | D22: =COUNTIF('2 Resolutions'!$D$5:$D$34,"Accept") | E22: =0 | F22: =COUNTIF('2 Resolutions'!$D$5:$D$34,"Disagree - return to decisions") | G22: =COUNTBLANK('2 Resolutions'!$D$5:$D$34)
A23: 3 Risks | B23: =COUNTA('3 Risks'!$A$5:$A$37) | C23: =B23-G23 | D23: =COUNTIF('3 Risks'!$F$5:$F$37,"Yes") | E23: =0 | F23: =COUNTIF('3 Risks'!$F$5:$F$37,"Discuss") | G23: =COUNTBLANK('3 Risks'!$F$5:$F$37)
A24: 4 Verification | B24: =COUNTA('4 Verification'!$A$5:$A$29) | C24: =B24-G24 | D24: =COUNTIF('4 Verification'!$D$5:$D$29,"Pass") | E24: =COUNTIF('4 Verification'!$D$5:$D$29,"Deferred") | F24: =COUNTIF('4 Verification'!$D$5:$D$29,"Fail") | G24: =COUNTBLANK('4 Verification'!$D$5:$D$29)+COUNTIF('4 Verification'!$D$5:$D$29,"Not yet run")
A25: 5 Checklist | B25: =COUNTA('5 Checklist'!$A$5:$A$46) | C25: =B25-G25 | D25: =COUNTIF('5 Checklist'!$D$5:$D$46,"Yes")+COUNTIF('5 Checklist'!$D$5:$D$46,"N/A") | E25: =0 | F25: =COUNTIF('5 Checklist'!$D$5:$D$46,"No") | G25: =COUNTBLANK('5 Checklist'!$D$5:$D$46)
A26: Total | B26: =SUM(B21:B25) | C26: =SUM(C21:C25) | D26: =SUM(D21:D25) | E26: =SUM(E21:E25) | F26: =SUM(F21:F25) | G26: =SUM(G21:G25)
A27: Positive / Hold / Negative map to each sheet's dropdown: Decisions = Confirmed / - / Changed my mind; Resolutions = Accept / - / Disagree; Risks = Yes / - / Discuss; Verification = Pass / Deferred / Fail, with Not yet run counted as Remaining; Checklist = Yes or N/A / - / No.
A30: Example of a completed decision row (format only, not editable, not counted; grey marks where your text would go)
A31: ID | B31: Decision | C31: Recommendation | D31: Blocks | E31: Your response | F31: Your answer or alternative | G31: Notes
A32: D0 | B32: Example: which mail client the node uses | C32: Client A | D32: Phase 2 | E32: Changed my mind | F32: Use client B, it already holds my accounts | G32: Discussed 2026-09-21

Sheet 1 Decisions
A1: 1 Decisions
A2: Section 19. All twenty-seven are closed. D15 (Secure Boot and the TPM binding) was decided on 2026-10-05 as option (a), Secure Boot enabled in the BIOS. D16 to D27 (v0.4.0) record the action register the Principal returned on 2026-10-16, every row approved as recommended (P-10 with the Principal's change); D16, D17 and D18 reopen D4 (the retrieval models), D10 (the vision engine) and D12 (Meditron), whose rows say so in their Note. D16, D18, D20, D22, D24 and D26 carry the Principal's answers of 2026-10-17 to the inputs they had left open (S56: the decode, prefill and deep-tier floors, the D-16 profile, no dedicated coder seat, EmbeddingGemma 2 dropped, the test-set and trial designs). D20 also records S57: the D-49 briefs are collected once ATLAS is live, from real examples.
A4: ID | B4: Decision | C4: Your answer (as given) | D4: Note | E4: Still stands? | F4: If changed, what instead
A5: D1 | B5: Inference backend: llama-server or Ollama | C5: llama-server, Ollama not installed | D5: Accepted as recommended | E5: Confirmed
A6: D2 | B6: Secure Boot: disable, or enrol keys | C6: Disabled on a headless node behind a firewall | D6: Accepted as recommended; superseded by D15 (enabled) | E6: Confirmed
A7: D3 | B7: Where the LUKS recovery key and restic passphrase live | C7: On the node and on an external USB drive | D7: Changed by the Principal. See R16: the USB copy is the one that survives node loss, so it must be stored away from the node | E7: Confirmed
A8: D4 | B8: Router model and embedding model | C8: Qwen3.5 4B-class instruct, bge-m3, bge-reranker-v2-m3 | D8: Accepted as recommended; reopened in v0.4.0 by D16 | E8: Confirmed
A9: D5 | B9: Whether the reserve domains are adopted | C9: Adopted now, with nine further areas supplied. Six new domains, five subspecialty folds | D9: Changed by the Principal (8.2, C24) | E9: Confirmed
A10: D6 | B10: Sentinel feed list | C10: CoinDesk, ASX and US index feed, RSS news, node telemetry | D10: Accepted as recommended | E10: Confirmed
A11: D7 | B11: Graph layer: GraphRAG or LightRAG | C11: LightRAG | D11: Accepted as recommended | E11: Confirmed
A12: D8 | B12: The never-without-the-Principal list | C12: The ten items in 16.3 are binding | D12: Accepted as recommended | E12: Confirmed
A13: D9 | B13: Retention rule for chats, logs, backups | C13: Defaults in 10.4 and 9.5 are binding | D13: Accepted as recommended | E13: Confirmed
A14: D10 | B14: Primary vision engine | C14: Qwen2.5-VL-72B at Q8_0, sole vision engine. GLM-4.6V-Flash and the 7B and 32B variants dropped | D14: Changed by the Principal: maximum quality, slow speed accepted (15.2, C25); reopened in v0.4.0 by D17 | E14: Confirmed
A15: D11 | B15: Apple .ipa build path | C15: Removed from the design. No Mac, no cloud runner, no macOS virtualisation. iOS source is still written, compiled elsewhere if Mac access ever exists | D15: Changed by the Principal | E15: Confirmed
A16: D12 | B16: Meditron-70B: include or skip | C16: Included in Phase 3 at Q8_0 | D16: Accepted, with "include now" noted; reopened in v0.4.0 by D18 | E16: Confirmed
... A31: D27 | B31: Hardware, drafters and the watch-list | C31: No discrete GPU now (D-62 option (a)); no second machine (D-63 option (a)); Lucebox's no-hardware ideas recorded on the watch-list (D-64 option (a)); the drafters kept in the disk set and decided per engine after the node speed tests, native MTP or DSpark only (D-61) | D31: Approved by the Principal on 2026-10-16 in the returned action register, as recommended (3.7, 15.4, 15.5) | E31: Confirmed

Sheet 2 Resolutions
A1: 2 Resolutions
A2: Section 18. C1 to C26 accepted in the workbook returned 2026-09-21; C27 (Ubuntu Server kept over Fedora 44 KDE Plasma) decided by the Principal on 2026-10-08; C28 to C30 (v0.4.0: the least-quantised rung that fits each seat alone, one vision engine on the GLM unit, one LLM seat resident at a time), superseding C23, C25 and C26, approved by the Principal on 2026-10-16 in the returned action register. Closed record; change a cell only to reopen one.
A4: ID | B4: Contradiction or ambiguity found | C4: Resolution adopted | D4: Your response | E4: Notes
A5: C1 | B5: Backend named as llama.cpp, then Ollama, then llama-server at different points | C5: llama-server primary on Vulkan; Ollama optional. D1 confirms | D5: Accept
A6: C2 | B6: Ubuntu 26.04 chosen, but Phase 4 needs ROCm PyTorch, which does not install cleanly on the 26.04 host. Out of date since v0.3.5 (S51): AMD's ROCm 10.0.0 support data lists this chip on 26.04 with the GA 7.0 kernel and the in-box driver, and 26.04's universe carries ROCm 7.1 (VERIFIED) | C6: ROCm lives inside containers; host runs Vulkan only (3.4). The resolution stands for the design's own reasons: isolation, exact pinning, and independence from Ubuntu's ROCm line (3.4, S51) | D6: Accept | E6: Reason corrected in v0.3.5 (S51, approved by the Principal 2026-10-11); the resolution stands
A7: C3 | B7: Windows 96 GB and Linux ~120 GB budgets both appeared | C7: Linux numbers are binding (4.1) | D7: Accept
A8: C4 | B8: KV-cache proposal mixed shipped features with unmerged research | C8: Only shipped features adopted (4.3) | D8: Accept
A9: C5 | B9: Meditron listed among PyTorch engines | C9: Runs through llama.cpp (5.1) | D9: Accept
A10: C6 | B10: Arthur's override bound to the abliterated engine "for legal dissection" | C10: Override is Qwen3.5 (6.1). *v0.4.0:* that override is now GLM-5.3-Flash, since Qwen3.5-122B-A10B left the roster (6.1) | D10: Accept | E10: Override restated in v0.4.0 (GLM-5.3-Flash replaces the retired Qwen3.5-122B-A10B); the addendum is unchanged
A11: C7 | B11: Gideon and Minerva bound to the abliterated engine "for zero-hallucination" | C11: Standard engine, retrieval-grounded (6.2) | D11: Accept
A12: C8 | B12: Router described as an Open WebUI pipeline | C12: Lives in the orchestrator; Filter is a relay (7.1) | D12: Accept
A13: C9 | B13: Domain 27 phrased as "memetic warfare" and "sentiment manipulation" | C13: Retained under Helena with phrasing softened to legitimate growth and attribution work | D13: Accept
A14: C10 | B14: Domain profiles' "Stateless MRTR, dispatch and decouple" removes the approval gate | C14: Isolated-context dispatch with tracked completion (8.6) | D14: Accept
A15: C11 | B15: Sentinel described as a WSL2 cron job | C15: systemd timer; there is no WSL (9.3) | D15: Accept
A16: C12 | B16: Sentinel fed to Ren | C16: Alaric and Silas under Arthur (9.3) | D16: Accept
A17: C13 | B17: AEGIS described as a single zip | C17: restic (9.5) | D17: Accept
A18: C14 | B18: AEGIS destination on the same drive | C18: Second drive plus optional external (9.5) | D18: Accept
A19: C15 | B19: Celery framed as freeing "a background hardware thread" for a backtest that may call an LLM | C19: CPU work decouples; GPU calls still serialise (9.7) | D19: Accept
A20: C16 | B20: Estate memory inside the vault versus the vault as on-demand top-secret storage | C20: Estate memory on the LUKS volume; vault content never persisted (10.5) | D20: Accept
A21: C17 | B21: Four engine names that do not exist | C21: Real replacements (15.3) | D21: Accept
A22: C18 | B22: "Vector Cortex replaces chat logs" versus Open WebUI's own database | C22: Supplements; retention rule under D9 (10.4) | D22: Accept
... A26: C22 | B26: Whether to adopt the amd64v3 or amd64v4 optimised archives | C26: Neither. The gain is on CPU-bound distribution packages, not GPU inference (3.1) | D26: Accept
A27: C23 | B27: Everything quantised to 4-bit under a 128 GB constraint that no longer exists | C27: Q8_0 for Nemotron, Qwen3.5, Qwen2.5-VL-72B and Meditron; MXFP4 retained for gpt-oss as its native form; Q4_K_XL for the Apex engine (5.1). Superseded by C28 in v0.4.0 | D27: Accept | E27: Superseded by C28 in v0.4.0 (approved by the Principal 2026-10-16 in the returned action register); kept as the record
A28: C24 | B28: Two domains held in reserve pending a stated need (old D5) | C28: Reserve closed. Six new domains, five subspecialty folds (8.2) | D28: Accept
A29: C25 | B29: Vision split across GLM-4.6V-Flash, Qwen2.5-VL-7B and a 32B that v0.1 wrongly said did not exist | C29: One engine: Qwen2.5-VL-72B at Q8_0. The 32B is real and official, but the Principal chose maximum quality (15.2). Superseded by C29 in v0.4.0 | D29: Accept | E29: Superseded by C29 in v0.4.0 (approved by the Principal 2026-10-16 in the returned action register); kept as the record
A30: C26 | B30: "Two engines at once" ambiguous between residency and generation | C30: Two may be resident; exactly one generates, everywhere, including Celery jobs (4.2). Superseded by C30 in v0.4.0 | D30: Accept | E30: Superseded by C30 in v0.4.0 (approved by the Principal 2026-10-16 in the returned action register); kept as the record
A31: C27 | B31: Ubuntu Server 26.04.1 versus Fedora 44 KDE Plasma, raised by the Principal on 2026-10-07 | C31: Ubuntu Server 26.04.1, re-confirmed 2026-10-08: five years without a major upgrade, a fixed kernel series, a dependable Remote Desktop login without autologin, AMD's vendor support for the chip, and no rewrite of the reviewed scripts (3.1). New in v0.3.4 | D31: Accept
A32: C28 | B32: C23's rule (the highest quantisation that leaves working headroom) sized files for a co-resident partner and kept DeepSeek-V4-Flash-0731 at UD-Q4_K_XL on a misread size; the Principal's directives of 2026-10-15 put result quality first | C32: Supersedes C23 (v0.4.0, approved by the Principal on 2026-10-16 in the returned action register; D-11 (a), D-29 (a), D-59 (b)). Each seat runs the least-quantised rung that fits it alone, with its measured quality cost stated: DeepSeek-V4-Flash-0731 at UD-Q8_K_XL (bit-exact), GLM-5.3-Flash at UD-IQ4_XS (the one lossy rung, provisional until T-03), gpt-oss-120b with an F16 trunk and its native MXFP4 experts; the KV cache at f16 where it is cheap, q8_0 elsewhere and q4_0 nowhere, the abliterated entry unchanged (Section 1, 4.3, 5.1) | D32: Accept | E32: New in v0.4.0, approved by the Principal 2026-10-16 in the returned action register (D-11 (a), D-29 (a), D-59 (b))
A33: C29 | B33: C25 made Qwen2.5-VL-72B at Q8_0 the one vision engine; with one LLM seat resident, a separate 79 GB vision engine would cost a swap for every image | C33: Supersedes C25 (v0.4.0, approved by the Principal on 2026-10-16 in the returned action register; D-20 (a), D-21 (a)). Still one vision engine: GLM-5.3-Flash with its glm5v projector on its own unit, so a look costs no swap while GLM is resident. Qwen2.5-VL-72B is retired. The phased OCR companion transcribes and does not reason, so it is not a second vision engine (5.1, 14.4, 15.2) | D33: Accept | E33: New in v0.4.0, approved by the Principal 2026-10-16 in the returned action register (D-20 (a), D-21 (a))
A34: C30 | B34: C26 read "two engines at once" as two resident and one generating; the two large Day 1 seats hold 147 to 151 GiB of weights each, so neither fits beside any other seat, and one seat at a time is made the rule for every seat | C34: Supersedes C26 (v0.4.0, approved by the Principal on 2026-10-16 in the returned action register; D-32 (a)). One LLM seat is resident at a time, and exactly one generation runs, everywhere, Celery jobs included. The limit is the setting ATLAS_ARBITER_MAX_RESIDENT (default 1, range 1 to 2), so two-seat residency can return without a code change; the companions, Chatterbox and the Phase 4 engines are not seats (4.2 rules 3 and 7) | D34: Accept | E34: New in v0.4.0, approved by the Principal 2026-10-16 in the returned action register (D-32 (a))

Sheet 3 Risks
A1: 3 Risks
A2: Section 20. R1 to R21 acknowledged in the workbook returned 2026-09-21; R22 and R23 (v0.3.2) and R24 and R25 (v0.3.4: the xrdp exposure and the unattended-reboot gap) acknowledged by the Principal on 2026-10-08. R23 is mitigated by D15 (Secure Boot enabled; the BIOS setting confirmed made on 2026-10-13). R26 to R28 (v0.3.5, S53, 2026-10-12: the ledger's 30-day purge not yet wired into the sweep, Chroma 1.5.9's soft deletes, and the once-silent failed sweep, now pushed to the phone) acknowledged by the Principal on 2026-10-13. R29 to R33 (v0.4.0, S-47: the re-pin, GLM-5.3-Flash's lossy rung, swap and re-prefill latency, the companions' share of the engine budget, the phased DeepSeek V4.1 trial engine) and R4, R17, R19 and R20 as restated in v0.4.0 acknowledged by the Principal on 2026-10-17 (S55). Later that day (S56) R9 (applicable, the node moving to the cable on its 10 GbE port) and R20 (lowered to Low) were restated with B-27 and R33's mitigation amended with D-47, both approved by the Principal with the other open-input recommendations.
A4: ID | B4: Risk | C4: Likelihood | D4: Impact | E4: Mitigation | F4: Acknowledged | G4: Notes
A5: R1 | B5: PyTorch on gfx1151 fails in Phase 4. As first written: no official gfx1151 wheel, and the community wheel may break on update. Amended (S15, S51): AMD now publishes the wheels (ROCm 10.0.0, torch 2.13.0); what remains is the open hang report #6530 (3.4); S51 pinned torchaudio, the one package that could have pulled a build for another ROCm version into the image | C5: High | D5: High for Phase 4, none for the LLM layer | E5: Pin versions (every package the Dockerfile names from AMD's index, torchaudio included since S51), per-engine pass/fail, containerised so the host is untouched | F5: Yes | G5: Amended in v0.3.5 (S51, approved by the Principal 2026-10-11): wheel and hang-report facts corrected
A6: R2 | B6: Ollama's Vulkan path immature on 26.04 | C6: Medium | D6: High if chosen | E6: D1: llama-server primary | F6: Yes
A7: R3 | B7: ROCm 7.2.x does not install on the 26.04 host kernel. Amended in v0.3.5 (S51): out of date, since AMD's ROCm 10.0.0 support data lists this chip on 26.04 with the GA 7.0 kernel and the in-box driver, and 26.04's universe carries ROCm 7.1 (VERIFIED) | C7: Low since S51 (was Certain) | D7: Medium | E7: Never install ROCm on the host, containers only (3.4), now for isolation, exact pinning and independence from Ubuntu's ROCm line | F7: Yes | G7: Amended in v0.3.5 (S51, approved by the Principal 2026-10-11): out of date, likelihood lowered from Certain to Low
A8: R4 | B8: KV quantisation silently falls back to full precision on an unsupported architecture. *Restated in v0.4.0 (S-48):* GLM-5.3-Flash and DeepSeek-V4-Flash-0731 run an f16 cache (D-29 option (a)), so on Day 1 only gpt-oss-120b, the router and the CPU pair, and the unchanged abliterated entry (q4_0, as in v0.3.5), run a quantised one. GLM may need flash attention off on Vulkan (T-04), which would rule out a quantised V cache for it. Each architecture prints its own number of KV proof lines (two on GLM, its attention and indexer caches), and a phased engine's count is set at its pull. The restatement was acknowledged by the Principal on 2026-10-17. | C8: Medium | D8: High, unexpected OOM | E8: V4 per-model check, on every proof line an engine prints (kv_proof_lines) | F8: Yes | G8: Restated in v0.4.0 (S-48, 2026-10-16); acknowledged 2026-10-17
A9: R5 | B9: A second engine loads before the first releases memory, node crashes | C9: Medium without an arbiter | D9: High | E9: Engine Arbiter polls GPU memory before every load (4.2) | F9: Yes
A10: R6 | B10: GraphRAG indexing is LLM-heavy and slow here | C10: High | D10: Medium | E10: Idle-time Celery job on the resident small model, D7 LightRAG | F10: Yes
A11: R7 | B11: Cloudflare token in a plain-text file | C11: Certain today | D11: High | E11: Scoped token, mode 600, outside backups and repo (12.3) | F11: Yes
A12: R8 | B12: Open WebUI phones home by default | C12: Certain unless hardened | D12: High for the zero-cloud rule | E12: Offline hardening in Phase 2 (12.1) | F12: Yes
A13: R9 | B13: 10GbE driver unavailable. *Restated in S56 (B-27, approved by the Principal on 2026-10-17): applicable,* since the node moves to the cable on its 10 GbE port not marked DASH. With it: a DASH-enabled port would expose an out-of-band management path on the LAN that ufw does not see (INFERRED), and Wi-Fi left on the LAN subnet can make the interface-bound DNS, ufw and DOCKER-USER rules drop traffic | C13: Low (was Not applicable): kernel 7.0's r8169 carries the RTL8127A family and handles its DASH variant, and linux-firmware ships rtl_nic/rtl8127a-1.fw (VERIFIED) | D13: Medium (was None): no LAN until Wi-Fi is set back as LAN_IFACE and Phase 1 step 4 is re-run | E13: Pre-flight notes the driver and MAC and warns, never stops, on the controller the driver treats as the DASH part, on Wi-Fi as LAN_IFACE and on a second interface on the LAN subnet; V1 records the driver and link speed and stays informational; the non-DASH port, with DASH left off; Wi-Fi taken off the LAN subnet (Section 22) | F13: Yes | G13: Restated in S56 (B-27, approved by the Principal 2026-10-17): applicable with the cable
A14: R19 | B14: DeepSeek V4 Flash llama.cpp support is newer than the other engines. *Generalised in v0.4.0 (S-26, S-47):* every engine whose support is newer than the rest; on Day 1 the Apex, DeepSeek-V4-Flash-0731, and GLM-5.3-Flash (glm5-next, first in b11279); at its pull Qwen3.8-Flash-Next (qwen4exp). The restatement was acknowledged by the Principal on 2026-10-17. | C14: Medium | D14: Medium for the Apex; high for GLM-5.3-Flash, which carries seven seats, vision and long documents | E14: Its own V22 row in the Phase 3 gate; a failure defers the engine without blocking the phase or the other engines, and its seats move to their recorded fallbacks by the Principal's decision (6.2, D-40) | F14: Yes | G14: Restated in v0.4.0 (S-26, S-47, 2026-10-16); acknowledged 2026-10-17
A15: R20 | B15: Wi-Fi throughput and stability over a ~690 GB download. *Restated in v0.4.0 (S-34):* about 448 GB in Phase 3 (D-42 option (b)), about 842 GB of phased engines in a later pull, about 1.9 TB in all (D-41 option (a)). The restatement was acknowledged by the Principal on 2026-10-17. *Restated again in S56 (B-27, approved by the Principal on 2026-10-17):* the node is on the cable, so Wi-Fi no longer applies. What remains is the rate one download stream gets from Hugging Face's CDN to Australia, unmeasured: 400 Mbps planned (about 2.5 hours for the 448 GB), about 5 hours at 200 Mbps; about 757 GB of phased engines, about 1.8 TB in all | C15: Low (was Medium) | D15: Low, time only | E15: Phases 3 and 4 detached and resumable; retries are free; only the core seats are pulled before Day 1's tests; the optional 60-second single-stream test sets DOWNLOAD_MBPS; parallel shard downloads (ATLAS_PULL_JOBS) for the phased pull after a short test | F15: Yes | G15: Restated in v0.4.0 (S-34, 2026-10-16); acknowledged 2026-10-17; restated again in S56 (B-27, approved by the Principal 2026-10-17): lowered to Low
A16: R21 | B16: XFCE and xrdp widen the surface beyond a headless server | C16: Low | D16: Medium | E16: Bound to LAN and WireGuard only, never internet-facing; no desktop autologin | F16: Yes
A17: R22 | B17: The atlas service user is in the docker group, which is root-equivalent on the host; the orchestrator needs the socket for the sandbox and Phase 4 containers | C17: Medium | D17: High if the orchestrator is ever compromised | E17: Accepted for Day 1 and recorded in every script header; Day 2 options are rootless Docker or a socket proxy that allows only the sandbox and engine images. New in v0.3.2 | F17: Yes | G17: Acknowledged 2026-10-08
A18: R23 | B18: TPM2 unlock bound to PCR 7 with Secure Boot disabled unseals for any boot medium (see D15) | C18: Medium | D18: High for physical theft of the node | E18: D15 closed as Secure Boot enabled (v0.3.3); the Principal confirmed the BIOS setting made on 2026-10-13 (workbook sheet 5), so the risk is mitigated subject to pre-flight's own check on Day 1: were it found off, pre-flight warns, V2 notes it and the to-do secure-boot stays open; the enrolment itself proceeds. New in v0.3.2 | F18: Yes | G18: Acknowledged 2026-10-08
A19: R24 | B19: xrdp is the LAN service with known unpatched flaws reachable before login: 26.04 packages 0.10.1 in universe, eighteen 2026 xrdp CVEs (fixed upstream in 0.10.6 and 0.10.6.1) are still "needs-triage" for 26.04, Ubuntu Pro's esm-apps carries no fix, and 0.10.1 runs as root. (SSH, Cockpit, Open WebUI and ntfy are also reachable before login from the LAN; none has a comparable open list.) | C19: Medium | D19: High (code execution as root) if a LAN device or a WireGuard peer is hostile | E19: v0.3.4: port 3389 only from the LAN subnet and WireGuard; the VNC proxy entry (vnc-any, the CVSS 9.8 CVE-2026-41252 path, also commented out upstream in 0.10.6.1), the NeutrinoRDP proxy entry (its module is not shipped) and Xvnc switched off; no root login, no alternate shell, TLS only; optional RDP_ALLOW_FROM (addresses inside the LAN, never the WireGuard bridge, checked before the firewall is touched) narrows the LAN side to the Principal's PC, and step 5b records the to-do with the LAN address the PC connected from. Residual: the remaining pre-login bugs from those hosts. Watch for a 26.04 xrdp security update; a later option is to keep 3389 on WireGuard only. New in v0.3.4 | F19: Yes | G19: Acknowledged 2026-10-08
A20: R25 | B20: Unattended upgrades install security updates from the release and security pockets but never reboot, and do not update Docker CE or Google Chrome (third-party repositories), so kernel and library fixes take effect only at the next reboot | C20: Medium | D20: Medium | E20: Accepted for Day 1: an automatic reboot would interrupt long jobs. Day 2: the live ATLAS reports "reboot required" and pending Docker CE/Chrome updates through ntfy and schedules the reboot with the Principal. New in v0.3.4 | F20: Yes | G20: Acknowledged 2026-10-08
A21: R26 | B21: The ledger's 30-day purge of operational rows (D9, 10.4) is written (Ledger.purge_expired, which refuses to run without an archive callback) but nothing calls it: arbiter_decisions, routing_decisions, tasks and decided approvals (30 days) and sentinel_pulses (365 days) grow without bound (VERIFIED at this commit; strikes are permanent by design) | C21: Certain that the tables grow; Low that it harms (one owner, small rows, a WAL SQLite file on the 8 TB drive, in every nightly backup) | D21: Low | E21: Phased item (S53, with the measurement layer in the first months): the sweep calls purge_expired with the cold archive as its callback. Until then the growth is slow and bounded only by disk, which Sentinel's hourly disk telemetry watches; the measurement layer also records the table sizes. New in v0.3.5 (S53) | F21: Yes | G21: Acknowledged 2026-10-13
A22: R27 | B22: The pinned Chroma 1.5.9 soft-deletes: a deleted vector is only marked in the HNSW index, labels are never reused, the index's capacity grows to the next power of two of everything ever added and never shrinks, and Chroma has no TTL (feature request #2139, open since 2024) and no compaction, so each collection's index tracks inserts ever, not live notes (VERIFIED in the source at the tag and in its hnswlib fork); a query falls back to brute force once more than a fifth of a small index is deleted | C22: Medium over years (chat turns are inserted and expire continually; Sentinel BLUFs yearly) | D22: Low (disk and RAM under the container's 8 GiB cap; one owner's volumes, roughly 4 to 6 KiB per vector, INFERRED) | E22: The sweep's measurement layer (phased, S53) records live counts per collection and cumulative inserts, the proxy for the tombstone count Chroma does not expose; a collection rebuild (re-insert the live documents into a fresh collection, re-embedding them, outside a backup freeze) when the inserted-ever to live ratio warrants it, as a Principal-approved maintenance proposal: W-CHROMA-REBUILD, at these volumes a yearly question at most. New in v0.3.5 (S53) | F22: Yes | G22: Acknowledged 2026-10-13
A23: R28 | B23: A sweep that failed inside the Celery worker was silent: atlas-prune.service touches its cadence stamp after a successful enqueue (no --wait), so systemd records success, nothing retries before the next 71-hour slot, and only the ledger's task row and the journal held the error; a broken store, a locked index or a full /srv/cold could have gone unnoticed for weeks (VERIFIED at e6cadea) | C23: Medium (any sweep failure; a long AEGIS freeze only spools, which is not a failure) | D23: Low (expired notes linger; nothing is lost, since the archive is written and verified before any delete) | E23: Since S53 the task pushes one ntfy line ("ATLAS prune: sweep failed", priority high) whether it raised or finished with errors, after the ledger row and before re-raising; the push can neither mask the error nor block the sweep. The sweep is still not retried before the next slot: the alert is what makes it visible, and the weekly summary with its two-in-a-row rule is a phased item. New in v0.3.5 (S53) | F23: Yes | G23: Acknowledged 2026-10-13
A24: R29 | B24: The re-pin changes every engine's behaviour: b11474 is 510 commits after v0.4.1, and the Vulkan fixes between them include wrong KV rows without flash attention (llama.cpp #28956) and flash-attention fixes (#29591, #29988), so results can depend on the -fa setting (UNVERIFIED on this node). New in v0.4.0 (S-47); acknowledged by the Principal on 2026-10-17 | C24: Medium | D24: High (every engine) | E24: V25, required at the Phase 3 gate: the old and new builds compared on gpt-oss-120b, DeepSeek-V4-Flash-0731 and the router, flash attention on for the verdict and off recorded (3.4). GLM-5.3-Flash cannot be compared, since the old pin cannot load it, so V4, V22, the coherence prompt, T-03 and T-04 carry its checks. The pin changes only by a deliberate edit | F24: Yes | G24: New in v0.4.0 (S-47, 2026-10-16); acknowledged 2026-10-17
A25: R30 | B25: GLM-5.3-Flash's only fitting rung is lossy (UD-IQ4_XS: published mean KLD 0.117, the same top token 88.2% of the time; UNVERIFIED on this node), and it carries seven seats, vision and long documents. New in v0.4.0 (S-47); acknowledged by the Principal on 2026-10-17 | C25: Certain that the rung is lossy; Medium that it matters on the Principal's work | D25: Medium to high: hard reasoning magnifies quantisation loss (INFERRED from the 2026 review) | E25: Provisional on every seat until the KLD run (D-02 option (c), T-03); the Phase 3 quality record and the to-do kld-run; the reasoning and Apex seats on the bit-exact DeepSeek-V4-Flash-0731; strong cross-checks on the other family (9.2); the Principal's test sets (D-49) | F25: Yes | G25: New in v0.4.0 (S-47, 2026-10-16); acknowledged 2026-10-17
A26: R31 | B26: Swap and re-prefill latency: with one LLM seat resident, every change of seat is a swap of about 50 to 85 seconds through LUKS, plus re-prefill of the task's context (DeepSeek-V4-Flash-0731 about 1.5 to 4.5 minutes at 16k to 32k and up to 13 at 64k; INFERRED until T-14). New in v0.4.0 (S-47); acknowledged by the Principal on 2026-10-17 | C26: Certain on every swap | D26: Medium (usability; nothing is lost) | E26: GLM-5.3-Flash carries most seats and stays resident (6.3); Deep Think phases are batched (9.1); on Day 1 each strong cross-check swaps on its own (9.2); deep runs are reserved for the Principal's acceptance (D-43, built, 9.1); Phase 3 records each swap; the phased swap batching and slot restore (4.4, 6.3; T-13, T-14) | F26: Yes | G26: New in v0.4.0 (S-47, 2026-10-16); acknowledged 2026-10-17
A27: R32 | B27: Companions shrink the engine budget: every resident GiB comes off every seat. GLM-5.3-Flash at 8 × 32k projects to 155.05 GiB against about 156 GiB expected and is refused below a MemTotal of about 186.1 GiB, and the CPU pair's host memory and the servers' host-RAM prompt caches sit at the edge of the Arbiter's budget or outside it (INFERRED). New in v0.4.0 (S-47); acknowledged by the Principal on 2026-10-17 | C27: Medium | D27: High for the seat refused (never an out-of-memory crash: the Arbiter refuses first) | E27: The Qwen3 pair on the CPU, charged its weights in full plus its measured anonymous memory, never below its projection (D-14 option (e)); Phase 3's measured footprints replace the projections (to-do kv-estimates); the relief orders of 4.1; the to-do cache-ram; the prompt-cache caps and the other host-RAM bounds of S55 (4.1, 4.4); the OCR companion's test re-checks the budget before it is added (5.3) | F27: Yes | G27: New in v0.4.0 (S-47, 2026-10-16); acknowledged 2026-10-17
A28: R33 | B28: The phased DeepSeek V4.1 trial engine: ROCm on gfx1151 for an LLM (stability with the inbox driver only; llama.cpp #25992, ROCm #6186), a fast-moving source (1,984 commits in six months for the Lucebox engine), published speeds measured with greedy sampling only, and a router-bias switch that trades fidelity for speed. New in v0.4.0 (S-47); acknowledged by the Principal on 2026-10-17 | C28: Medium, after Day 1 only | D28: Low (evaluation only, outside the routed roster) | E28: Phased (15.5); the inbox amdgpu driver only, no DKMS, locked memory for that container alone, the image digest, source commit and file hashes pinned and never refreshed by themselves (D-52, D-57, B-36, B-37); speeds measured greedy and at the node's own temperatures, not 1.0 alone (D-47, S56); approximate switches only in scored trials (16.1 rule 9); promotion only by a blind-scored win (T-30) | F28: Yes | G28: New in v0.4.0 (S-47, 2026-10-16); acknowledged 2026-10-17; mitigation amended in S56 (D-47, approved by the Principal 2026-10-17)
A29: R10 | B29: Sustained thermal load in a small chassis | C29: Medium | D29: Low | E29: Monitor temperatures in Cockpit; the chip's configurable ceiling is 120 W and the Principal is adding external cooling | F29: Yes
A30: R11 | B30: CGNAT prevents inbound WireGuard | C30: Low, port forward already succeeded | D30: High for remote access | E30: V5 from mobile data, static IP from the ISP if needed | F30: Yes
A31: R12 | B31: Fictitious directors corresponding as humans, AI non-disclosure | C31: Medium | D31: Medium to high, legal | E31: Gideon's sensitive-tier check, approval gate, 16.5 | F31: Yes
A32: R13 | B32: Abliterated engine used for external output | C32: Medium | D32: Medium | E32: Abliterated output always passes the same gate, never routine tier | F32: Yes
A33: R14 | B33: Chatterbox continuation quirk in production speech | C33: Medium | D33: Low | E33: V7 testing, Kokoro fallback per line | F33: Yes
A34: R15 | B34: Prompt bloat from domain injection makes every dispatch slow | C34: High without limits | D34: High, usability | E34: Three-card limit, compact cards, stable-prefix ordering (8.4, 4.4) | F34: Yes
A35: R16 | B35: Backup passphrase or LUKS key lost with the node | C35: Low | D35: Catastrophic | E35: Sharpened under D3. The Principal keeps a copy on the node and on an external USB drive. The on-node copy is convenience only; the USB copy is the one that matters, and it must live away from the node, since a fire or burglary that takes the node takes anything beside it. Quarterly restore test | F35: Yes
A36: R17 | B36: PyAnnote gated model not accepted, diarisation silently absent. *Restated in v0.4.0 (S-48, C-06):* the gated pipeline is now speaker-diarization-community-1 (CC-BY-4.0, an automatically approved form). Once the phased Nemotron 3 Diarization (OpenMDW-1.1, not gated) is primary, community-1 is only its fallback for recordings with more than eight speakers, and the risk narrows to that case. The restatement was acknowledged by the Principal on 2026-10-17. | C36: Medium | D36: Low | E36: V6, recorded deferred with the to-do input-hf-token while the token or the licence is missing | F36: Yes | G36: Restated in v0.4.0 (S-48, C-06, 2026-10-16); acknowledged 2026-10-17
A37: R18 | B37: Continuous vision enabled by drift rather than decision | C37: Low | D37: High, privacy | E37: Separate capability flag under Alaric, logged, D8 item 7 | F37: Yes

Sheet 4 Verification
A1: 4 Verification
A2: Section 21 (V1 to V25; V25, the output parity of the llama.cpp re-pin, is new in v0.4.0, its pass marks confirmed by the Principal on 2026-10-17, and V21 now proves single residency). Filled in during Day 1 as each phase gate runs. Nothing is trusted until its row reads Pass.
A4: ID | B4: What Day 1 must prove | C4: Where | D4: Result | E4: Evidence or notes
A5: V1 | B5: Network link up and stable. Informational only, not a gate. *S56 (B-27):* on the cable it records the driver and the link speed (ethtool's Speed: line, else sysfs) and warns below 2,500 Mb/s; Wi-Fi is recorded as before | C5: Phase 1 pre-flight | D5: Not yet run
A6: V2 | B6: fTPM present and enabled, TPM2 enrolment succeeds | C6: Phase 1 step 2 | D6: Not yet run
A7: V3 | B7: Kernel parameters accepted on 7.0 and the GTT pool matches them (Phase 1; since S48 the same check also proves the crash settings: no crashkernel= on the booted command line and no crash-kernel memory reserved, exactly one panic=10, kernel.panic 10 and kernel.panic_on_oops 0; since S49 also exactly one kho=, the literal kho=off, and no CMA memory: no kexec handover scratch and no named CMA area); llama-cli --list-devices then lists the GPU as Vulkan0 with at least the larger of 160000 MiB (156.25 GiB) and the largest Day 1 seat with its context memory as the Arbiter projects it (v0.4.0, D-36 option (c), S-28: 155.05 GiB for GLM-5.3-Flash on Day 1, so 160000 MiB stands; the weights alone before the venv exists) of Vulkan device memory, and records the figure, which is not the engine budget (Phase 2); the measured heap decides every rung above about 149 GiB (T-01). rocminfo's gfx1151 confirmation sits in the Phase 4 container under V11 | C7: Phase 1 gate, then Phase 2 gate | D7: Not yet run
A8: V4 | B8: Quantised KV cache actually applied per model, no silent fallback (v0.4.0, S-48: the requested type, f16 included, on every proof line an engine prints; kv_proof_lines is four on DeepSeek-V4-Flash-0731 and two on GLM-5.3-Flash and gpt-oss-120b) | C8: Phase 3 step 2 | D8: Not yet run
A9: V5 | B9: WireGuard reachable from mobile data via vpn.sovereign-node.link | C9: Phase 1 step 7 | D9: Not yet run
A10: V6 | B10: The pyannote gated pipeline accepted and loading: speaker-diarization-community-1 since v0.4.0 (C-06; it was 3.1, which V6 now probes only as a diagnostic when community-1 is refused) | C10: Phase 2 step 5 | D10: Not yet run
A11: V7 | B11: Voice casting listening test, Alaric and Gideon clones sourced | C11: Phase 2 gate | D11: Not yet run
A12: V8 | B12: PointLLM builds and runs on ROCm in the container | C12: Phase 4 step 4 | D12: Not yet run
A13: V9 | B13: Clay or Prithvi builds and runs | C13: Phase 4 step 4 | D13: Not yet run
A14: V10 | B14: Every Day 1 LLM seat (gpt-oss-120b, its abliterated twin, GLM-5.3-Flash and DeepSeek-V4-Flash-0731) loads, generates, swaps and releases memory at its fixed quantisation. *v0.4.0 (S-24, S-25; D-33 option (c)):* decode is recorded beside each seat's projection and fails only below a per-seat floor the Principal sets. *S56 (D-33, D-47, approved by the Principal on 2026-10-17):* the floors are set at 8k, gpt-oss-120b 25, GLM-5.3-Flash 6 and DeepSeek-V4-Flash-0731 4 tok/s, judged on the slower of the 512 and 8k points with at least 64 generated tokens; the 8k prefill fails below 200, 40 and 40; the placement checks fail a partial offload or a GTT delta under 0.85 × the weights (a line not found is UNKNOWN); a review line at 70% of the projection raises the to-do decode-review and never fails; the Apex line carries T-06's 8k decode with DSpark off. The abliterated entry keeps its v0.3.5 band and rule; the GLM and Apex lines point to their V22 rows. Eleanor's resident 4B router model is verified separately at the Phase 2 gate (V10a), since it is pulled there; since S56 V10a also times 128 tokens at temperature 0 and fails below the router's 20 tok/s floor, read from engines.json; below its review line (70% of its projection's low end) Phase 2 raises the to-do decode-review-router, never a fail | C14: Phase 3 gate | D14: Not yet run
A15: V11 | B15: Inside the ROCm container: rocminfo reports gfx1151, and AMD's gfx1151 PyTorch wheels (pinned ROCm 10.0.0 / torch 2.13.0 / torchvision 0.28.0 / torchaudio 2.11.0.2) pass tensor, matmul and diffusion self-tests; since S51 torchaudio's installed version must also be exactly the pin, 2.11.0.2+rocm10.0.0 (whether it imports is recorded, not required: an import failure fails CosyVoice 2 and Stable Audio Open, not Phase 4) | C15: Phase 4 step 1 | D15: Not yet run
A16: V12 | B16: Open WebUI makes no outbound connection after hardening (verified with the firewall log) | C16: Phase 2 step 3 | D16: Not yet run
... A29: V25 | B29: Output parity between the pin b11474 and the old pin v0.4.1 (new in v0.4.0, S-02; the condition D-01 set on the pin): on the chat engines both builds load (gpt-oss-120b, DeepSeek-V4-Flash-0731, the router), base logits for 16 × 512 tokens of the domain profiles written by the old build and scored by the new with --kl-divergence, and a 24-task deterministic set run on both. The verdict is taken with flash attention on (off is recorded): a mean KLD of at most 0.01, the same top token at least 98% of the time and no fewer tasks correct (thresholds confirmed by the Principal on 2026-10-17, S55). A file the old build cannot load records deferred; GLM-5.3-Flash and the embedder and reranker are listed as not covered | C29: Phase 3 step 2b; Phase 3 gate (required) | D29: Not yet run

Sheet 5 Checklist
A1: 5 Checklist
A2: Section 22. The original rows were ticked in the workbook returned 2026-09-21; the rows added or reopened since were closed as each records: D15 decided and the Windows share deferred on 2026-10-05, C27 decided and R22 to R25 acknowledged by the Principal on 2026-10-08, the Secure Boot BIOS setting, the USB recovery drive and R26 to R28 ticked in the workbook returned 2026-10-13, and the action register, its licences, C28 to C30 and D16 to D27 ticked on 2026-10-16 (v0.4.0), R29 to R33 with the restated R4, R17, R19 and R20 acknowledged on 2026-10-17, and later that day the answers to the open inputs, the bandwidth and R9 and R20 as restated (S56). S57 records the Principal's statements the same day: the states answered (VIC, NSW and QLD, with the Commonwealth), the briefs collected once ATLAS is live, the standards list a new open row, and the MedGemma decision a task for the live ATLAS with the Principal present. Blank rows: the optional items the scripts ask for at a prompt (Yes when provided, N/A to leave them for the live ATLAS to-do list); the inputs still left to the Principal, each already built with its stated default and kept as a to-do (the seat profiles and reasoning settings; the HAI-DEF decision for MedGemma, taken with the live ATLAS; and after Day 1 the briefs for the seat test sets, from real examples, the standards list, the TF_OMEGA situations and the T-03 coding tasks); and the optional 60-second download test. One row is to do before Phase 1: row 32, the cable on the 10 GbE port not marked DASH, with the reservation and the forward moved to its MAC and Wi-Fi off the LAN subnet (S56; pre-flight warns, never stops, if it is not done). The Secure Boot row and the install rows are ticked. One request still stands on row 29, to confirm that the installer's encryption option (Encrypt the LVM group with LUKS) was taken; pre-flight checks the OS volume on Day 1, and an unencrypted one is a warning and the to-do os-volume-encryption, never a stop.
A4: # | B4: Group | C4: Item | D4: Done | E4: Notes
A5: 1 | B5: Principal's actions — what is genuinely left | C5: Answer D1 through D14. Done, all fourteen closed in Section 19. | D5: Yes
A6: 2 | B6: Principal's actions — what is genuinely left | C6: New in v0.4.0: return the action register (64 decisions D-01 to D-64, 12 named models, 18 persona rows, 12 companions, 60 structure rows, 80 baseline items and 33 tests). Returned by the Principal on 2026-10-16, every row approved, P-10 and P-17 marked "Approve with changes" (P-10 with a change and a question, answered in 5.3; P-17 is among the uncensored-seat items, unchanged by this revision; N-01 and N-03 with a question, answered in 4.1 and 4.2); recorded as D16 to D27 (Section 19). | D6: Yes
A7: 3 | B7: Principal's actions — what is genuinely left | C7: New in v0.4.0: accept the Qwen Community License 1.0 for Qwen3.8-Flash-Next (D-03), the NVIDIA Nemotron Open Model License for Nemotron 3 Super (D-04) and OpenMDW-1.1 for Nemotron 3 Diarization (D-05). Accepted by the Principal on 2026-10-16 in the returned action register; each applies when its phased engine is pulled. | D7: Yes
A8: 4 | B8: Principal's actions — what is genuinely left | C8: New in v0.4.0: accept the remaining licences with each engine as it is approved (D-34 option (b), D-35 option (a)): MIT for GLM-5.3-Flash, DeepSeek-V4-Flash-0731 and Ling-3.0-flash-Fin; Apache 2.0 for the Qwen3 embedder and reranker, Intern-S1 and Baichuan-M3 (Qwen3-Coder-Next and EmbeddingGemma 2 left the arsenal on 2026-10-17, D-19 (c), D-60 (b)); CC-BY-4.0 for pyannote community-1; and, with their phased companions, the OCR, speech, voice and image licences D-35 names. Accepted by the Principal on 2026-10-16 in the returned action register. The Hugging Face click-through for community-1 is part of the token box below. MedGemma 1.5 4B's HAI-DEF terms are not among these (C-12; the open box below). | D8: Yes
A9: 5 | B9: Principal's actions — what is genuinely left | C9: Decide where the LUKS recovery key and restic passphrase live (D3). Done: node plus external USB. | D9: Yes
A10: 6 | B10: Principal's actions — what is genuinely left | C10: Confirm the Sentinel feed list (D6), the director alias pattern (D14), and the Apple build path (D11, removed). | D10: Yes
A11: 7 | B11: Principal's actions — what is genuinely left | C11: Have the USB recovery drive present on Day 1 and write it at the Day 1 close-out: the LUKS recovery key (shown once in Phase 1 step 2), the restic passphrase (/etc/atlas/secrets/restic.pass, shown once in Phase 2 step 7) and the vault passphrase you chose (step 9b); then store it away from the node, not beside it (R16). Drive in hand, confirmed by the Principal on 2026-10-13; the writing itself stays a Day 1 close-out step. *Reworded in v0.3.2: the material does not exist before Day 1, so the drive cannot be "stored" yet.* | D11: Yes
A12: 8 | B12: Principal's actions — what is genuinely left | C12: New in v0.4.0 (B-25, approved by the Principal on 2026-10-16): initialise the real gocryptfs vault before Day 1 and choose its passphrase: from a console, run sudo env ATLAS_VAULT_INIT=1 ./atlas-day1.sh phase2 --force 09b, then write the passphrase and the master key (shown once) with the other secrets for the USB drive (above). A plain phase2 proves the mechanics on a throw-away vault and records V18 deferred (Section 11, 17). | D12: Yes
A13: 9 | B13: Principal's actions — what is genuinely left | C13: New in v0.3.3: enable Secure Boot in the BIOS before Phase 1 (D15, option (a)). The one BIOS change since the workbook; without it pre-flight warns and the to-do secure-boot stays open, nothing stops. Done, confirmed by the Principal on 2026-10-13; pre-flight verifies it on Day 1. | D13: Yes
A14: 10 | B14: Principal's actions — what is genuinely left | C14: Optional, asked at the prompt (v0.3.3): your SSH public key, pasted when Phase 1 step 1 asks (the step prints the PowerShell command that shows it); skipped, password SSH stays on until the key is added (to-do ssh-key).
A15: 11 | B15: Principal's actions — what is genuinely left | C15: Optional, asked at the prompt (v0.3.3): GOOGLE_ACCOUNTS (two addresses, each tagged corporate or estate), FAMILY_NAMES (for the router's hard rule) and BUILDFARM_ACCEPT_ANDROID_SDK_LICENCE (Google's Android SDK licence, needed by the build container) are asked once by the first run, with an example each; a skip records a to-do and the dependent step defers itself. WINDOWS_SHARE is not asked (Section 12.4: live to-do).
A16: 12 | B16: Principal's actions — what is genuinely left | C16: ~~/etc/atlas/secrets/smb.cred for the Windows share account~~ Deferred to the live ATLAS (v0.3.3) with the share itself; Phase 2 step 9 is skipped. No action before Day 1. | D16: Yes
A17: 13 | B17: Principal's actions — what is genuinely left | C17: Decide D15 (Secure Boot and the TPM binding). Done 2026-10-05: option (a). | D17: Yes
A18: 14 | B18: Principal's actions — what is genuinely left | C18: Create the Google Cloud OAuth client for Gmail, Calendar and Drive, and be reachable for roughly five minutes during the Phase 2 pause (V20). Client created. The consent click itself still happens during Phase 2; Google requires the account owner to click Allow. The client must be of the Desktop app type (its JSON has a top-level installed key; a web key is the wrong type and Phase 2 stops at minute 0 saying so). Drop the JSON into /srv/atlas/staging/inbox/google-oauth-client.json once Phase 1 has created that folder. | D18: Yes
A19: 15 | B19: Principal's actions — what is genuinely left | C19: Optional, asked at the prompt (v0.3.1, relaxed in v0.3.3): create a Hugging Face access token (read scope) and, with the same account, accept the licences of the gated models on huggingface.co: pyannote/speaker-diarization-community-1 (V6; since v0.4.0, C-06, the one pyannote repository V6 needs, so pyannote/speaker-diarization-3.1 and pyannote/segmentation-3.0 are no longer required), black-forest-labs/FLUX.1-dev and stabilityai/stable-audio-open-1.0 (Phase 4). Phase 2 asks for the token once at its start (hidden input) and stores it under /etc/atlas/secrets/; skipped, V6 and the gated Phase 4 engines are deferred with the to-do input-hf-token. The four Phase 3 repositories are public, so Day 1 needs no further gated licence (v0.4.0).
A20: 16 | B20: Principal's actions — what is genuinely left | C20: Answered by the Principal on 2026-10-17 (S56): the inputs v0.4.0's approved rows had left open, from the open-input research: the per-seat decode floors and the deep-tier floor (D-33, D-47: 25, 6, 4 and 20 tok/s at 8k, prefill floors 200, 40 and 40, 4 tok/s for the deep tier; Section 1, 9.1, V10); the context targets of Baichuan-M3 and Intern-S1 (D-16: Q5_K_S with a rotated q8_0 cache at 1 × 32,768, Baichuan-M3 on the i1 file, Intern-S1 text only; 4.1, 5.1); no dedicated coder seat (D-19 (c): GLM-5.3-Flash codes, provisional until T-03); EmbeddingGemma 2 dropped (D-60 (b), 15.5); MedGemma 1.5 4B only on conditions, Rad-DINO alone until they hold (C-12, 15.2); the designs of the seat test sets and the trial set (D-49, D-46; 6.2, 15.5); and the bandwidth (B-27: a 2,000 Mbps line, 400 Mbps planned for the single-stream pull, the cable on the 10 GbE port not marked DASH to a 2.5 GbE router port; 2, 15.4). decode-floors is no longer raised while every seat has a floor, and context-targets is answered. | D20: Yes
A21: 17 | B21: Principal's actions — what is genuinely left | C21: Open, not needed for Day 1 (v0.4.0): the inputs still left to the Principal, each built with its stated default and kept as a to-do: the DeepSeek-V4-Flash-0731 context target (default 131,072 tokens, 4.3), GLM-5.3-Flash's cache type and slot profile (T-04, D-48; default f16 at 8 × 32k without --kv-unified, 4.3) and the long-document trigger (D-38, S-30; default 24,000 tokens, 7.1) (to-do seat-profiles); each seat's fixed reasoning setting (D-30 (b); the provisional settings of 5.1, in the to-do kld-run).
A22: 18 | B22: Principal's actions — what is genuinely left | C22: Open, a task for the live ATLAS with the Principal present (S56, C-12; S57): accept or decline Google's HAI-DEF Terms of Use and Prohibited Use Policy for MedGemma 1.5 4B. Not needed for Day 1. After Day 1 ATLAS raises it and shows a plain summary of both, with their links (15.2); no script raises it on Day 1. The Principal decides. On a yes, the Principal accepts on the model's Hugging Face page with their own account, never ATLAS (16.3 item 2); ATLAS records the date and the terms version in the ledger, like pyannote's, then pulls MedGemma 1.5 4B and runs the node test against GLM-5.3-Flash's own vision. Accepting means no diagnosis, a licensed clinician making any real decision, no serving to anyone else, family members' images only with their consent, an indemnity to Google, and every copy deleted if Google terminates (California law). Declining, or leaving it, keeps Rad-DINO alone, with GLM-5.3-Flash's own vision reading scans (15.2).
A23: 19 | B23: Principal's actions — what is genuinely left | C23: Optional (S56, B-27): before Phase 3, time one 60-second download on any computer on the same line: curl -L -o /dev/null --max-time 60 -w '%{speed_download}\n' https://huggingface.co/unsloth/DeepSeek-V4-Flash-0731-GGUF/resolve/main/UD-Q8_K_XL/DeepSeek-V4-Flash-0731-UD-Q8_K_XL-00003-of-00005.gguf (on Windows curl.exe, with -o NUL). It prints bytes per second: × 8 ÷ 1,000,000 gives Mbit/s. Set DOWNLOAD_MBPS in /etc/atlas/atlas.env to about 0.8 × that. Skipped, 400 stands (15.4).
A24: 20 | B24: Principal's actions — what is genuinely left | C24: Open, after Day 1 (v0.4.0; the set design approved on 2026-10-17, S56; S57): for the test sets of Australian law, HR, aviation, logistics, AEC, SCADA, game design, growth marketing, customer success and physical security / OSINT: a brief of about 15 minutes per domain (the 3 to 5 kinds of task you would give that seat, and 2 or 3 redacted real examples where they exist, which stay on the node), collected once ATLAS is live, from real examples as the work progresses (the Principal, 2026-10-17); the standards list (the box below); then approval or edits of ATLAS's drafts, wave by wave, and blind grades for the escalations and the 10% calibration sample (D-49 option (a), T-27; to-do seat-test-sets). Your states of operation are answered: VIC, NSW and QLD, with the Commonwealth (S57, Section 1). Awaiting the Principal, not decided: spreading wave 1's 16 Australian-law tasks across the Commonwealth, VIC, NSW and QLD, and adding about 10 Australian tax and finance tasks (6.2). Until the sets are scored, GLM-5.3-Flash carries those seats unproven (6.2).
A25: 21 | B25: Principal's actions — what is genuinely left | C25: Open, for the live ATLAS (S57): the list of Australian Standards you hold or subscribe to, with each licence's terms checked: whether it allows storing and processing the text in a private system. ATLAS holds the text of only those; every other standard it cites by number, edition and what free sources say, never its clauses (8.4). Accepting or renewing a licence stays your own act (16.3 item 2). Until the list is given, no standard's text is held. It also serves the D-49 test sets (to-do seat-test-sets).
