Workbook

Sheet Summary
A1: A.T.L.A.S. Action Register
A2: Every open action and recommendation from the research of 13 to 15 October 2026 (the roster refresh, the specialist LLM arsenal and the Lucebox study) and the items still open in the baseline v0.3.5, for the Principal's response. Nothing in the repository has been changed; the structure is amended only after this workbook is returned.
A4: How to use this workbook
A5: 1. Each sheet lists items with the recommendation in the blue column. The yellow cells are yours: Your response (dropdown), Your choice or alternative, and Your comments. Do not edit the other cells.
A6: 2. Your response: Approve (take the recommendation as written), Approve with changes (write the change in the next cell), Reject, Defer (decide later), Need more info (say what you need). Sheet 6 also offers Done.
A7: 3. Work sheet 1 (Decisions) first. Sheets 2 to 4 follow from it, and sheet 5 lists the document, script and workbook amendments that each approved decision would trigger, citing the decision IDs it depends on.
A8: 4. Sheet 7 lists the measurements on the node that settle the open quality questions; approving a test adds it to the Phase 3 test plan.
A9: 5. Speeds and quality figures are projections or full-precision results until the node measures them. Sources are the reports and notes under reports/ and research_notes/ in the repository.
A10: 6. The progress table below updates as you answer. Return the workbook when done; each approved structure change is then made, checked and committed.
A12: Example of a completed row (illustration only, not an item)
A13: ID | B13: D-00
A14: Item | B14: Move the llama.cpp pin to a newer release
A15: Recommendation | B15: Move to v0.6.0 with an output-parity test
A16: Your response | B16: Approve with changes
A17: Your choice or alternative | B17: v0.6.0, not b11474
A18: Your comments | B18: Run the parity test on gpt-oss-120b before the other engines
A20: Progress
A21: Sheet | B21: Items | C21: Approve | D21: Approve with changes | E21: Reject | F21: Defer | G21: Need more info | H21: Done | I21: Answered | J21: Outstanding
A22: 1 Decisions | B22: =COUNTA('1 Decisions'!$A$5:$A$68) -> 64 | C22: =COUNTIF('1 Decisions'!$J$5:$J$68,"Approve") -> 0 | D22: =COUNTIF('1 Decisions'!$J$5:$J$68,"Approve with changes") -> 0 | E22: =COUNTIF('1 Decisions'!$J$5:$J$68,"Reject") -> 0 | F22: =COUNTIF('1 Decisions'!$J$5:$J$68,"Defer") -> 0 | G22: =COUNTIF('1 Decisions'!$J$5:$J$68,"Need more info") -> 0 | H22: =COUNTIF('1 Decisions'!$J$5:$J$68,"Done") -> 0 | I22: =COUNTA('1 Decisions'!$J$5:$J$68) -> 0 | J22: =B22-I22 -> 64
A23: 2 Named models | B23: =COUNTA('2 Named models'!$A$5:$A$16) -> 12 | C23: =COUNTIF('2 Named models'!$I$5:$I$16,"Approve") -> 0 | D23: =COUNTIF('2 Named models'!$I$5:$I$16,"Approve with changes") -> 0 | E23: =COUNTIF('2 Named models'!$I$5:$I$16,"Reject") -> 0 | F23: =COUNTIF('2 Named models'!$I$5:$I$16,"Defer") -> 0 | G23: =COUNTIF('2 Named models'!$I$5:$I$16,"Need more info") -> 0 | H23: =COUNTIF('2 Named models'!$I$5:$I$16,"Done") -> 0 | I23: =COUNTA('2 Named models'!$I$5:$I$16) -> 0 | J23: =B23-I23 -> 12
A24: 3 Persona allocation | B24: =COUNTA('3 Persona allocation'!$A$5:$A$22) -> 18 | C24: =COUNTIF('3 Persona allocation'!$K$5:$K$22,"Approve") -> 0 | D24: =COUNTIF('3 Persona allocation'!$K$5:$K$22,"Approve with changes") -> 0 | E24: =COUNTIF('3 Persona allocation'!$K$5:$K$22,"Reject") -> 0 | F24: =COUNTIF('3 Persona allocation'!$K$5:$K$22,"Defer") -> 0 | G24: =COUNTIF('3 Persona allocation'!$K$5:$K$22,"Need more info") -> 0 | H24: =COUNTIF('3 Persona allocation'!$K$5:$K$22,"Done") -> 0 | I24: =COUNTA('3 Persona allocation'!$K$5:$K$22) -> 0 | J24: =B24-I24 -> 18
A25: 4 Companions | B25: =COUNTA('4 Companions'!$A$5:$A$16) -> 12 | C25: =COUNTIF('4 Companions'!$I$5:$I$16,"Approve") -> 0 | D25: =COUNTIF('4 Companions'!$I$5:$I$16,"Approve with changes") -> 0 | E25: =COUNTIF('4 Companions'!$I$5:$I$16,"Reject") -> 0 | F25: =COUNTIF('4 Companions'!$I$5:$I$16,"Defer") -> 0 | G25: =COUNTIF('4 Companions'!$I$5:$I$16,"Need more info") -> 0 | H25: =COUNTIF('4 Companions'!$I$5:$I$16,"Done") -> 0 | I25: =COUNTA('4 Companions'!$I$5:$I$16) -> 0 | J25: =B25-I25 -> 12
A26: 5 Structure changes | B26: =COUNTA('5 Structure changes'!$A$5:$A$64) -> 60 | C26: =COUNTIF('5 Structure changes'!$H$5:$H$64,"Approve") -> 0 | D26: =COUNTIF('5 Structure changes'!$H$5:$H$64,"Approve with changes") -> 0 | E26: =COUNTIF('5 Structure changes'!$H$5:$H$64,"Reject") -> 0 | F26: =COUNTIF('5 Structure changes'!$H$5:$H$64,"Defer") -> 0 | G26: =COUNTIF('5 Structure changes'!$H$5:$H$64,"Need more info") -> 0 | H26: =COUNTIF('5 Structure changes'!$H$5:$H$64,"Done") -> 0 | I26: =COUNTA('5 Structure changes'!$H$5:$H$64) -> 0 | J26: =B26-I26 -> 60
A27: 6 Baseline open items | B27: =COUNTA('6 Baseline open items'!$A$5:$A$84) -> 80 | C27: =COUNTIF('6 Baseline open items'!$H$5:$H$84,"Approve") -> 0 | D27: =COUNTIF('6 Baseline open items'!$H$5:$H$84,"Approve with changes") -> 0 | E27: =COUNTIF('6 Baseline open items'!$H$5:$H$84,"Reject") -> 0 | F27: =COUNTIF('6 Baseline open items'!$H$5:$H$84,"Defer") -> 0 | G27: =COUNTIF('6 Baseline open items'!$H$5:$H$84,"Need more info") -> 0 | H27: =COUNTIF('6 Baseline open items'!$H$5:$H$84,"Done") -> 0 | I27: =COUNTA('6 Baseline open items'!$H$5:$H$84) -> 0 | J27: =B27-I27 -> 80
A28: 7 Node tests | B28: =COUNTA('7 Node tests'!$A$5:$A$37) -> 33 | C28: =COUNTIF('7 Node tests'!$F$5:$F$37,"Approve") -> 0 | D28: =COUNTIF('7 Node tests'!$F$5:$F$37,"Approve with changes") -> 0 | E28: =COUNTIF('7 Node tests'!$F$5:$F$37,"Reject") -> 0 | F28: =COUNTIF('7 Node tests'!$F$5:$F$37,"Defer") -> 0 | G28: =COUNTIF('7 Node tests'!$F$5:$F$37,"Need more info") -> 0 | H28: =COUNTIF('7 Node tests'!$F$5:$F$37,"Done") -> 0 | I28: =COUNTA('7 Node tests'!$F$5:$F$37) -> 0 | J28: =B28-I28 -> 33
A29: Total | B29: =SUM(B22:B28) -> 279 | C29: =SUM(C22:C28) -> 0 | D29: =SUM(D22:D28) -> 0 | E29: =SUM(E22:E28) -> 0 | F29: =SUM(F22:F28) -> 0 | G29: =SUM(G22:G28) -> 0 | H29: =SUM(H22:H28) -> 0 | I29: =SUM(I22:I28) -> 0 | J29: =SUM(J22:J28) -> 279
A31: Sources (in the repository)
A32: reports/ATLAS specialist LLM arsenal.md (2026-10-15) and research_notes/ATLAS specialist LLM arsenal/
A33: reports/Lucebox engine and memory hierarchy.md (2026-10-15) and research_notes/Lucebox engine and memory hierarchy/
A34: reports/ATLAS LLM roster refresh 2026.md (2026-10-13, addendum 2026-10-14) and research_notes/ATLAS LLM roster refresh 2026/
A35: docs/ATLAS_FRAMEWORK_REVIEW.md v0.3.5 and docs/ATLAS_BUILD_BASELINE.xlsx (the baseline and its workbook)

Sheet 1 Decisions
A1: Decisions
A2: Decisions the Principal must make before the structure is amended. Work this sheet first: sheets 2 to 5 depend on it.
A4: ID | B4: Area | C4: Decision required | D4: Options | E4: Recommendation | F4: Why (evidence) | G4: Priority | H4: Depends on | I4: Source | J4: Your response | K4: Your choice or alternative | L4: Your comments
A5: D-01 | B5: llama.cpp pin | C5: Move the node's llama.cpp off v0.4.1 (commit b29c606, build tag b10964, 2026-09-14), and to which build? | D5: (a) keep v0.4.1: GLM-5.3-Flash, EmbeddingGemma 2 and K2-Horizon cannot load, Flash-Next runs an incomplete Vulkan path; (b) v0.6.0 (2026-10-05): GLM (#27773), Flash-Next MTP (#29761) and hyper-connection ops (#28988), Nemotron MTP (#29018), MiMo (#29257), rerank batch fix (#28876), Vulkan fixes; (c) b11474 (2026-10-07): (b) plus EmbeddingGemma 2, K2-Horizon and GLM MTP (#29928); (d) newest b11643 (2026-10-15). | E5: (c) b11474, or (b) v0.6.0 if EmbeddingGemma 2 (b11452), K2-Horizon (b11454) and GLM MTP (b11474) are not needed. Only the arsenal report recommends a re-pin (b11474 or v0.6.0); the roster research lists what a post-pin build would add but recommends no re-pin. Adopt only after the output-parity test T-02; b11330 is the floor for Flash-Next. It changes every engine's behaviour, so it needs explicit approval. | F5: GLM-5.3-Flash, the arsenal's main engine, needs glm5-next (b11279 / v0.6.0), and under the new rules most strong candidates and several speed and retrieval fixes are post-pin. Vulkan correctness fixes after the pin include #28956 (wrong KV rows without flash attention) and FA fixes #29591 / #29988. No build yet has a llama-server TTS endpoint (PR #26603). | G5: Before any change | H5: T-02 | I5: Arsenal report Inputs L97; Arsenal CR G1 (L40-69). Roster report Addendum L126; Roster gap_closure L363, L415-L425.
A6: D-02 | B6: Top seats: precision versus quality | C6: Which engine leads the top seats: GLM-5.3-Flash at a lossy 4-bit rung, or DeepSeek-V4-Flash-0731 at a lossless rung? | D6: (a) GLM-5.3-Flash UD-IQ4_XS 156.82 GB / 146.05 GiB (KLD 0.117, 88.2% top-1) for its board lead; (b) DeepSeek-V4-Flash-0731 UD-Q8_K_XL 161.87 GB / 150.75 GiB (bit-exact) and accept the lower index score; (c) decide per seat after the node KLD run. | E6: (c): run the KLD test T-03 first; meanwhile professional-knowledge and long-context seats default to GLM, and reasoning and Apex seats to the lossless V4-Flash. | F6: GLM leads in-envelope (AA 41.8 vs 34.3; LegalBench 83.93%, Finance Agent v2 57.85%, MedScribe 88.94%, AA-LCR 80.0), but every board score is full precision, and hard reasoning amplifies quantisation loss 3-10x (a 3.5-bit GLM lost 1.4 MMLU-Pro and 4.9 maths points). The roster research rejected GLM as 3-bit only (UD-Q3_K_XL 147.54 GB); the arsenal research found the IQ4_XS rung and governs LLM seats. | G6: Before any change | H6: D-01 (GLM cannot load at v0.4.1); T-03 | I6: Arsenal report Inputs L96, quantisation rule L72. Roster report L35, L56, L86.
A7: D-03 | B7: Licence: Qwen3.8-Flash-Next | C7: Accept the Qwen Community License 1.0 for Qwen3.8-Flash-Next? | D7: (a) accept; (b) reject and drop Flash-Next (runner-up for Ren and Victor, Deep Think third opinion). | E7: (a) accept: internal use is exempt. | F7: Flash-Next is AA 39.8 (second of the twelve) and its UD-Q6_K_XL (169.17 GB / 157.55 GiB) is KLD 0.0271 against 0.0266 for its own Q8_0. Both research rounds read the licence. | G7: Before any change | I7: Arsenal report Inputs L98, verdict row 7 (L48). Roster report Addendum L130.
A8: D-04 | B8: Licence: Nemotron 3 Super | C8: Accept the NVIDIA Nemotron Open Model License for Nemotron 3 Super? | D8: (a) accept; (b) reject and drop Nemotron 3 Super (long-context utility, long-document runner-up). | E8: (a) accept. | F8: Licence text (2025-12-15): commercial use and derivatives allowed, no claim on outputs, no safety or acceptable-use clause; redistribution needs the licence and an NVIDIA notice; terminates on patent or copyright litigation. engines.json L90 still marks it unverified. It also makes an abliterated Nemotron licence-compatible for private use. | G8: Before any change | I8: Arsenal report Inputs L98; Arsenal CR G5 (L134-141). Roster gap_closure L403-L413.
A9: D-05 | B9: Licence: OpenMDW-1.1 | C9: Accept OpenMDW-1.1 for Nemotron 3 Diarization and, if chosen, the Nemotron-3-Embed-8B embedder? | D9: (a) accept; (b) reject: keep pyannote (community-1) for diarisation and a Qwen3 embedder. | E9: (a) accept. | F9: Nemotron 3 Diarization is the best open diariser on the only same-harness comparison (OpenBench average DER 0.19 vs pyannote community-1 0.28); Nemotron-3-Embed-8B leads RTEB (75.45). | G9: Before any change | I9: Arsenal report Inputs L98, verdict row 12 (L53).
A10: D-06 | B10: Uncensored: Mistral Large 2 Uncensored | C10: Reject the named Ollama build gdisney/mistral-large-uncensored? | D10: (a) reject; (b) reject it but admit the weight-edited XORTRON (2411 Heretic) Q8_0 130.28 GB / 121.33 GiB at about 1.7 tok/s; (c) admit the named Q4_0 build 69.08 GB / 64.34 GiB. | E10: (a) reject; (b) only if the Principal wants the Mistral lineage and accepts about 1.7 tok/s. | F10: The artefact is stock Mistral-Large-2407 at legacy Q4_0 plus a system prompt that instructs misinformation, under the research and non-commercial MRL licence; stock 2411 already scores UGI W/10 7.5 with no prompt. Mistral Large 3 (Apache 2.0) fits only at 1 bit (UD-TQ1_0 157.03 GiB). | G10: Before any change | I10: Arsenal report Inputs L98, L100, verdict row 6 (L47); Arsenal CR G6 (L143-151).
A11: D-07 | B11: Uncensored: Valerie's default engine | C11: Which uncensored engine is Valerie's default for cyber and AEGIS work (Alaric shares it)? | D11: (a) MiMo-V2.6-Flash uncensored (dealignai RL-UNCENSORED, AliceThirty MXFP4 168.42 GB / 156.85 GiB, MIT, about 18 tok/s); (b) gpt-oss-120b Derestricted Q8_0 124.30 GB / 115.76 GiB (Apache 2.0, about 37-39 tok/s projected); (c) keep the current huihui/noctrex gpt-oss file (the roster research's choice). | E11: (a) MiMo uncensored, after the re-pin and the load test T-09; (b) is the fallback. | F11: Its base leads Vals CyberBench among open models (75.36%), and it is the only large 2026 uncensored build with published retention (MMLU 83.41% vs base 83.56%; HarmBench compliance 99.69%, thinking off). It fits with about 7 GiB spare only if companions do not cut the ~164 GiB budget (D-14). Contradiction: the roster research says MiMo needs a pin after 2026-09-22 (#29257); the arsenal review (C6) found the mimo2 runtime already in v0.4.1 and only the converter later, so loading at the pin is plausible but untested. | G11: Before any change | H11: D-01; T-09; T-10 | I11: Arsenal report Inputs L99, uncensored L82; Arsenal CR G4 (L123-128), C6 (L235). Roster report L38; Roster gap_closure L378, L463.
A12: D-08 | B12: Uncensored: explicit-override seat | C12: Which build serves the explicit-override uncensored seat behind Ren's and Arthur's uncensored prefixes? | D12: (a) ArliAI gpt-oss-120b Derestricted Q8_0 124.30 GB / 115.76 GiB; (b) Derestricted MXFP4_MOE (gghfez) 63.39 GB / 59.03 GiB; (c) keep the current huihui v2 / noctrex MXFP4_MOE file; (d) abliterated Qwen3.5-122B-A10B Q8_0 129.87 GB / 120.95 GiB (mradermacher or wangzhang v2; the roster research's pick). | E12: (a) Derestricted Q8_0; (d) only as a second option after a node refusal and KLD check (T-10). | F12: Derestricted raises UGI NatInt above base (35.70 vs 33.68) where the huihui abliteration fell to 16.72; Apache 2.0; a Q8_0 of the edited BF16 keeps the edited experts near BF16, while re-quantising to MXFP4 adds fresh error. The 122B builds have no refusal or quality data (Heretic and huihui cost KLD about 0.06 on Qwen3.5-27B), and the arsenal governs LLM seats. | G12: Before any change | H12: D-21 (Qwen3.5-122B kept or not); T-10 | I12: Arsenal report Inputs L99, uncensored L82; Arsenal CR G4 (L118-122). Roster report L80, L110, Addendum L140; Roster gap_closure L392.
A13: D-09 | B13: Uncensored: retire the current abliterated file | C13: Retire the node's current abliterated engine (huihui v2 -> noctrex MXFP4_MOE, key gpt-oss-120b-abliterated, 63.39 GB / 59.03 GiB)? | D13: (a) retire it and remove it from the Phase 3 pull; (b) keep it only until a replacement passes a node test (the roster research's choice); (c) keep it as a standing fallback. | E13: (a) retire it; (b) would pull 63 GB only to benchmark a file the arsenal does not use. | F13: No provenance card and no refusal, KL or benchmark data, and huihui's source repositories now return HTTP 401. The Heretic alternatives are worse than Derestricted (kldzj v2 KL 0.53 with 22/100 refusals; v1 0.92). | G13: Before any change | H13: D-07; D-08 | I13: Arsenal report Inputs L99, uncensored L82, verdict row 10 (L51). Roster report L80, L108, Addendum L140; Roster gap_closure L349, L393, L455.
A14: D-10 | B14: Persona and agent allocation map | C14: Adopt the per-persona allocation (sheet 3) as the new engine map? | D14: (a) adopt as given: GLM-5.3-Flash for Ren, Gideon, Silas, Helena, Victor, Minerva (primary), vision and long documents; V4-Flash for Arthur and the Apex; MiMo uncensored for Valerie and Alaric; Qwen3.5-4B for Eleanor; (b) adopt with seat changes the Principal names; (c) defer until the node tests. | E14: (a), with GLM's seats provisional until the KLD run T-03. | F14: GLM is the measured leader wherever a professional board exists, and under sequential operation every seat gets the full ~164 GiB, so co-residency no longer justifies a smaller engine for Ren; the cost is the 4-bit rung and the re-pin. It replaces gpt-oss-120b (Corporate) and Nemotron (Estate) as defaults (D-12, D-13). | G14: Before any change | H14: D-01; D-02 | I14: Arsenal report allocation L13-34. Roster report core seats L66-L67.
A15: D-11 | B15: Apex / TF_OMEGA engine and rung | C15: Keep DeepSeek-V4-Flash-0731 as the Apex / TF_OMEGA engine and move it from UD-Q4_K_XL to the lossless UD-Q8_K_XL? | D15: (a) UD-Q8_K_XL 161.87 GB / 150.75 GiB, bit-exact on all 1,328 tensors (unsloth/DeepSeek-V4-Flash-0731-GGUF); (b) keep UD-Q4_K_XL 155.10 GB / 144.44 GiB (KLD 0.0102, 96.28% same top token, about 11 tok/s); (c) GLM-5.3-Flash UD-IQ4_XS (AA 41.8, lossy) if the KLD run favours it; (d) K2-Horizon-375B IQ3_XXS 150.81 GiB (AA 31, needs b11454). | E15: (a) until the KLD run decides, with the fit confirmed by the Phase 3 KV measurement T-06. The arsenal, roster and Lucebox reports agree. | F15: Bit-exact, HLE 38.6, GPQA 90.8; the dsv4 cache is about 6,880 B/token, so UD-Q8_K_XL leaves about 13 GiB of ~164 GiB, not the 2 GiB Section 5.1 states (it read 161.9 GB as GiB and used the Arbiter's 327,680 B/token). No UD-Q6_K_XL exists, and unsloth/DeepSeek-V4-Flash-GGUF holds the preview, not 0731. Decode about 7 tok/s on mainline Vulkan (a floor; in-pin kernels unmeasured). | G15: Before any change | H15: D-02; T-03; T-06 | I15: Arsenal report TF_OMEGA row L28, what changed L88; Arsenal CR C1 (L230). Roster report L68, L86, Addendum L128, L136. Lucebox report Inputs row 1 (L392).
A16: D-12 | B16: gpt-oss-120b role | C16: Confirm dropping gpt-oss-120b as the Corporate default (Ren, Helena, Victor, Gideon, Minerva) and demote it to a fast utility, drafting and Sentinel-escalation engine? | D16: (a) demote; (b) keep it as the default resident engine (Section 6.3; the roster research's recommendation); (c) promote Qwen3.5-122B-A10B Q8_0 to the default (the roster's no-download fallback). | E16: (a) demote, and take the seat engines from D-10. | F16: AA 11.6 makes it a speed engine, not a quality seat; its 63.39 GB (59.03 GiB) earned the default only under co-residency, which the run-alone directive removes. It stays lossless at native MXFP4 and the fastest engine: 57-60 tok/s projected by the arsenal, 53.8-55.6 measured on 128 GB boxes (roster). | G16: Before any change | H16: D-10 | I16: Arsenal report directives L7, verdict row 9 (L50), what changed L88. Roster report L66, L82, Addendum L134.
A17: D-13 | B17: Nemotron 3 Super role | C17: Confirm dropping Nemotron 3 Super Q8_0 as the Estate default (Arthur, Silas, Alaric) and keep it as a long-context utility? | D17: (a) keep it as the Estate default (the roster research's recommendation); (b) Arthur to DeepSeek-V4-Flash-0731 UD-Q8_K_XL, Nemotron kept as long-context utility and long-document runner-up; (c) keep it as default for Silas and Alaric only. | E17: (b). | F17: AA 12.8 against 34.3 for V4-Flash, its card discloses an HLE/GPQA contamination risk, and it has no MTP at the pin (#29018). It earns a place by a 1M-token context at tiny KV (about 44 GiB spare) and calibrated refusals (RefusalBench 0.4% benign refused, 89.3% of should-refuse refused). Its Q8_0 is 128.47 GB / 119.65 GiB, not 120-123 GB. | G17: Before any change | H17: D-10; T-12 | I17: Roster report L67, L84; Roster gap_closure L380, L418, L451. Arsenal report verdict row 8 (L49).
A18: D-14 | B18: Companion residency versus engine budget | C18: Where do the upgraded retrieval companions live, given that every GiB resident on the iGPU comes off every engine's budget? | D18: (a) Qwen3-Embedding-8B + Qwen3-Reranker-8B resident (7.49 + 7.49 GiB; budget about 150 GiB); (b) the 4B pair resident (about +6.7 GiB; budget about 157 GiB); (c) 8B embedder + 4B reranker (about +10.2 GiB); (d) load the retrieval pair on demand; (e) run it on the CPU; (f) keep bge-m3 + bge-reranker-v2-m3 (1.3 GiB) until the engine set is fixed. | E18: Choose companions and LLM rungs together. If MiMo stays Valerie's default (D-07) and Flash-Next stays at UD-Q6_K_XL, take (d) or (e); otherwise (b), the 4B pair the roster research named only as its alternative (its first pick, like the arsenal's, is the 8B pair (a)), with Flash-Next at UD-Q5_K_XL (D-28). Neither report sizes this fully; T-15 measures it. | F18: The Arbiter budgets pool minus the measured GPU resident set (6-8 GiB today) minus 16 GiB. At about 150 GiB, V4-Flash UD-Q8_K_XL (150.75), the 5-bit 235B-class rungs (150.76-150.84), Flash-Next UD-Q6_K_XL (157.55) and MiMo (156.85) stop fitting; at about 157 GiB Flash-Next and MiMo still do not. The 4B pair keeps most of the gain (MTEB multilingual 69.45 vs 70.58; MMTEB-R 72.74 vs 72.94; bge pair 59.56 / 58.36). A resident OCR model adds about 1.3-1.5 GiB. | G18: Before any change | H18: D-07; T-15 | I18: Arsenal CR G9 (L194-204); Arsenal report companions L84. Roster report L75, L100; Roster gap_closure L73-L75.
A19: D-15 | B19: Medical cross-check | C19: Replace Meditron-70B with Baichuan-M3-235B as Minerva's cross-check, and drop MedGemma-27B as the fallback? | D19: (a) Baichuan-M3 (mradermacher Q5_K_S 161.88 GB / 150.76 GiB, or official baichuan-inc Q4_K_M 143.78 GB / 133.91 GiB; Apache 2.0; 8-13 tok/s projected); (b) Apertus-70B-MeditronFO Q8_0 69.87 GiB (dense, about 3 tok/s); (c) keep Meditron-70B (about 74 GB, 4K context, about 3 tok/s); (d) MedGemma-27B Q8_0 28.71 GB (under the 70B floor). | E19: (a), with the rung set by D-16; drop (d). GLM stays Minerva's primary. | F19: Meditron is a 2023 Llama-2-70B continued pre-train with no instruction tuning (52.9% on an independent 2026 neurology exam, lowest of the 70B models); Apertus-MeditronFO averages 53.77. Baichuan-M3 has an official GGUF and vendor HealthBench 65.1 / Hard 44.4 (gpt-oss-120b 57.6 / 30.0) but no independent score, so T-11 checks it. | G19: Before any change | H19: D-16; T-11 | I19: Arsenal report Minerva row L23, what changed L88; Arsenal CR section 5 (L262). Roster report L71, L96, Addendum L132, L140; Roster gap_closure L390, L431.
A20: D-16 | B20: Context targets: medical and science seats | C20: What context must the medical cross-check (Baichuan-M3) and the science seat (Intern-S1) support? | D20: (a) Q5_K_S (Baichuan 150.76 GiB, Intern-S1 150.84 GiB): about 23K context after a 9 GiB allowance; (b) Q4_K_M (Baichuan official 133.91 GiB, Intern-S1 132.86 GiB) for longer context. | E20: State a target context per seat: Q5_K_S if about 20-23K tokens is enough, Q4_K_M otherwise. | F20: These Qwen3-235B-shaped engines carry about 188 KiB/token of f16 KV (192,512 B); 5-bit is near reference (+0.63-0.75% PPL), while 4-bit costs 3.7-5.0 points on AIME and GPQA. GLM, Flash-Next, Nemotron and V4-Flash reach their native windows. | G20: Before any change | H20: D-14 | I20: Arsenal report Inputs L102, quantisation table L69. Roster gap_closure L390.
A21: D-17 | B21: Science seat | C21: Add Intern-S1 as the science engine for domains 15, 35 and 36 (Minerva; Valerie with Minerva)? | D21: (a) add Intern-S1 (bartowski Q5_K_S 161.96 GB / 150.84 GiB) as an override engine; (b) leave science on GLM-5.3-Flash. | E21: (a). | F21: Vendor ChemBench 83.4, MatBench 75.0, ProteinLMBench 63.1 (no independent board); Apache 2.0; qwen3moe at the pin; 10-13 tok/s projected. It carries the Qwen3-235B lineage forward; Intern-S2-397B fits only at 2 bits. | G21: Before any change | H21: D-16 | I21: Arsenal report science row L31, what changed L88; Arsenal CR G7 (L153-166).
A22: D-18 | B22: Finance seat | C22: Add Ling-3.0-flash-Fin as Silas's finance-tuned, lossless second engine? | D22: (a) add Ling-3.0-flash-Fin Q8_0 135.63 GB / 126.32 GiB as Silas's override or second opinion; (b) GLM-5.3-Flash only. | E22: (a), with GLM kept as Silas's primary. | F22: Finance Agent v2 54.93% against GLM's 57.85%, but lossless Q8_0 inside the pin at 22.6-30.2 tok/s projected (corrected for C7; no gfx1151 measurement); MIT. LegalBench 68.74% and AA 23 make it a finance engine, not a general CFO engine. | G22: Before any change | I22: Arsenal report Silas row L20, what changed L88; verification_other_large_specialists rows 3-6.
A23: D-19 | B23: Coder seat | C23: Add a dedicated coder seat with Qwen3-Coder-Next, at which rung, and confirm dropping Qwen3.8-27B? | D23: (a) Qwen3-Coder-Next Q8_0 84.81 GB / 78.99 GiB (37-44 tok/s projected); (b) BF16 159.46 GB / 148.51 GiB (unquantised, 256K context, about 9 tok/s projected on Vulkan); (c) no dedicated seat, GLM-5.3-Flash covers coding; (d) Qwen3.8-27B Q8_0 29.05 GB co-resident (the roster research's pick, now under the 70B floor). | E23: Drop (d). (a) if a dedicated seat is wanted; (b) only if unquantised weights are worth a fourfold speed loss; otherwise (c). | F23: Coder-Next is just above the floor (79.7B total, 3B active) and inside the pin; vendor SWE-bench Verified 70.6-71.3 and Aider polyglot 66.2, but AA 9.24, and GLM beats it on SWE-bench (92%, Vals). Fixed-harness runs put open models 15-20 points below vendor tables. Its Apache 2.0 rests on the card (LICENSE file missing). The arsenal table lists BF16, its verdict calls Q8_0 practical. | G23: Before any change | I23: Arsenal report coder row L32, verdict row 4 (L45), quantisation table L67. Roster report L70, L90, Addendum L128, L134; Roster gap_closure L61-L63, L412.
A24: D-20 | B24: Vision engine | C24: Which engine becomes the single vision engine now that it need not pair, and is the co-resident light vision tier dropped? | D24: (a) GLM-5.3-Flash + glm5v mmproj (UD-IQ4_XS + 0.65 GB; needs the re-pin); (b) Qwen3-VL-235B Q5_K_S 161.88 GB / 150.76 GiB + 1.16 GB mmproj (at the pin); (c) Flash-Next UD-Q6_K_XL + 0.62 GB mmproj; (d) Qwen3.5-122B-A10B Q8_0 + mmproj-BF16 (the roster's at-pin pick); (e) keep Qwen2.5-VL-72B Q8_0 79 GB; (f) a 27-31B co-resident light tier (Qwen3.8-27B or Gemma 4 31B, under the 70B floor). | E24: (a) after the re-pin, (b) if the pin stays at v0.4.1; drop (e) and (f). A small OCR companion (C-04) transcribes scanned documents. | F24: GLM is LMArena vision #23 (top open) and Vals MMMU 86.01%, and on its own unit vision costs no swap while GLM is resident; Qwen3-VL-235B is OmniDocBench 89.78; Qwen2.5-VL-72B is MMMU 70.2 at about 3 tok/s. The light tier existed only to pair with gpt-oss (Qwen3.8-27B 29.05 GB, Gemma 4 31B 32.64 GB; MMMU-Pro 76.3 / 73.4). | G24: Before any change | H24: D-01; T-17 | I24: Arsenal report vision row L29, what changed L88; Arsenal CR G3 (L93-104). Roster report L72, L88, L98, Addendum L134; Roster gap_closure L430, L444.
A25: D-21 | B25: Engines leaving the core set | C25: Retire Qwen2.5-VL-72B, Meditron-70B and Qwen3.5-122B-A10B from the roster and the Phase 3 pull? | D25: (a) retire all three: vision to D-20, cross-check to Baichuan-M3, long documents to GLM (Nemotron Q8_0 runner-up); (b) keep Qwen3.5-122B-A10B Q8_0 MTP build (132.55 GB / 123.45 GiB) + mmproj as an at-pin long-document and vision fallback until GLM runs on an approved pin (the roster research's pick); (c) keep any of them on disk as a fallback. | E25: (a). | F25: None is in the arsenal's ten-engine set, and their seats are reassigned (GLM AA-LCR 80.0, MRCR 128K 62.9). Qwen3.5-122B scores AA 16 against GLM's 41.8, and the arsenal covers the at-pin case with Qwen3-VL-235B (vision) and Nemotron (1M context). Retiring the 72B (79 GB) and Meditron (74 GB) also removes the gpt-oss + vision pairing. The arsenal report does not name Qwen3.5-122B; its retirement is inferred from the allocation. | G25: Before any change | H25: D-10; D-15; D-20 | I25: Arsenal report allocation L29-30, sequential L78, what changed L88. Roster report L69, L71, L72, L88, L96, L98; Roster gap_closure L374, L384, L430. FRAMEWORK_REVIEW 19 D10, D12.
A26: D-22 | B26: Deep Think engine pair | C26: Replace the gpt-oss-120b generator and Nemotron adversary with a two-family GLM-5.3-Flash + DeepSeek-V4-Flash-0731 pair, Flash-Next as third opinion? | D26: (a) GLM and V4-Flash (Ren's and Arthur's engines), Flash-Next third opinion; (b) any two families among GLM, V4-Flash, MiMo and Flash-Next; (c) keep the baseline pair. | E26: (a). | F26: Diversity comes free under sequential operation: two architectures and two training recipes for only swap latency (about 50-85 s per swap). AA HLE 39.9 / 38.6 and GPQA 91.2 / 90.8. | G26: Before any change | H26: D-10 | I26: Arsenal report Deep Think row L27, allocation points L34.
A27: D-23 | B27: Default resident engine and batching | C27: Batch queued work by engine and keep the most-used engine (GLM-5.3-Flash) resident by default? | D27: (a) adopt: route a hemisphere's or persona's queued work to the resident engine before swapping, GLM resident by default; (b) keep gpt-oss-120b resident by default (Section 6.3). | E27: (a). | F27: A resident 145-160 GiB engine leaves only about 10-25 GiB of page cache, so switching between two large engines is a full cold read (25-70 s; 50-85 s per swap realistic); fast engines (gpt-oss-120b 63.39 GB / 59.03 GiB, Nemotron 3 Super Q8_0 128.47 GB / 119.65 GiB) recover page cache. | G27: Before any change | H27: D-10; T-14 | I27: Arsenal report sequential L76-78.
A28: D-24 | B28: Slow dense engines and 3-bit rungs | C28: Exclude dense 70-123B engines and 3-bit-only engines from the primary arsenal? | D28: (a) exclude both classes; (b) admit a dense uncensored Mistral (XORTRON Q8_0) only on explicit request; (c) admit 3-bit engines (Llama 4 Maverick, Qwen3.5-397B UD-IQ3_XXS, K2-Horizon-375B IQ3_XXS, GLM-4.x). | E28: (a); (b) only if the Principal wants that lineage and accepts about 1.7 tok/s. | F28: Dense Mistral Large / XORTRON, Mistral Medium 3.5, Devstral 2 and Kimi-Dev decode at about 1.7-3.3 tok/s; 3-bit rungs sit in the risky band (KLD about 0.03-0.18, about 5 maths points lost). Intern-S2-397B fits only at 2 bits, Mistral Large 3 only at 1 bit, and Mistral Small 4 runs its experts on the CPU at the pin (0.82 tok/s). | G28: Before any change | I28: Arsenal report Inputs L100; Arsenal CR G6, G7 (L143-166). Roster report L37, L41, L52; Roster gap_closure L375, L379.
A29: D-25 | B29: Baseline revision type | C29: Is the arsenal change recorded as a new baseline version that reopens closed decisions D4, D10 and D12 and supersedes C23, C25 and C26, or as Section 23 S-rows only? | D29: (a) v0.4.0 with new D-rows from D16, new C-rows from C28 and one S54 row for the script corrections; (b) v0.3.6 with S-rows only. | E29: (a). | F29: Section 23 defines S-rows as corrections of literals that reopen no decision, while the arsenal replaces the D4 retrieval models, the D10 vision engine, the D12 Meditron inclusion and the C23, C25 and C26 resolutions. The header still reads 'Closed build baseline'. | G29: Before any change | I29: FRAMEWORK_REVIEW L11, L1142, C23-C26 L996-L999, D4-D12 L1011-L1019.
A30: D-26 | B30: Day 1 scope of the change | C30: Does the amended structure go into Day 1, or does Day 1 run on the v0.3.5 roster and migrate afterwards? | D30: (a) amend everything before Day 1; (b) run Day 1 on v0.3.5 and migrate after; (c) amend the pin, roster, residency rule, Arbiter units and Phase 3 list before Day 1, and phase the specialist seats, slot save/restore, swap batching, the speech and image companions and the V4.1 trial after Day 1. | E30: (c). | F30: Nothing has been executed. v0.3.5 would pull about 690 GB (about 15 h at 100 Mbps), of which Qwen2.5-VL-72B (79 GB), Meditron-70B (74 GB) and the abliterated file (63 GB) are to be retired, and V21 would prove a pair production no longer runs; the orchestrator features are not needed to bring the node up. | G30: Before any change | H30: D-25 | I30: FRAMEWORK_REVIEW 17 Phase 3 step 1 (L945), 21 V21 (L1085); Arsenal report Inputs.
A31: D-27 | B31: Workbook builder in the repository | C31: Commit the builder that produces docs/ATLAS_BUILD_BASELINE.xlsx to the repository before the amendment? | D31: (a) commit it beside scripts/day1/tools/fill-workbook.py; (b) keep it outside the repository. | E31: (a). | F31: The builder exists only in a session scratchpad (r54/build.py); every baseline change since v0.3.4 rebuilt the workbook from it, and this change touches at least eleven of its fifteen sheets. | G31: Before any change | H31: D-25 | I31: scratchpad r54/build.py L207-L245; docs/ATLAS_BUILD_BASELINE.xlsx (15 sheets).
A32: D-28 | B32: Qwen3.8-Flash-Next file | C32: Which Qwen3.8-Flash-Next file is pulled? | D32: (a) unsloth UD-Q6_K_XL 169.17 GB / 157.55 GiB (KLD 0.0271), about 6.5 GiB left for KV; (b) ggml-org Q8_0 162.62 GB / 151.46 GiB: its header is already read (per_layer_token_embd, the n-gram table, at Q4_0 = 28.80 GB; every other matrix Q8_0), so only its KLD is unmeasured (T-08); (c) unsloth UD-Q5_K_XL 158.29 GB / 147.42 GiB, more room for context and companions; (d) do not adopt it. The unsloth Q8_0 (188.23 GB / 175.30 GiB) does not fit. | E32: (a), unless T-08 shows the ggml-org Q8_0 is near-lossless; (c) if D-14 or a long context leaves no room for (a). | F32: UD-Q6_K_XL matches its own Q8_0 (KLD 0.0271 vs 0.0266); the roster research had found no in-budget file meeting the precision rule. AA 39.8, GPQA 92.3, Terminal-Bench 2.1 86.1. MTP (#29761) and the Vulkan hyper-connection ops (#28988) are post-pin: measured only at UD-IQ4_XS on 128 GB Ryzen AI Max+ 395 boxes: 26.9-27.2 tok/s without MTP (the roster infers v0.4.1 gets this) and 41.3 with MTP on PR #28243 fork builds; nothing is measured at UD-Q6_K_XL (23-29 tok/s projected). | G32: Before Day 1 | H32: D-01; D-03; D-14; T-08 | I32: Arsenal report verdict row 7 (L48). Roster report Addendum L126, L128, L130, L136; Roster gap_closure L373, L374, L396.
A33: D-29 | B33: KV cache precision for every seat | C33: Which KV cache type does each seat run under the less-quantisation rule, including the Apex ladder? | D33: (a) f16 where the cache is cheap (GLM 19,712 B/token, V4-Flash about 6,880 B/token), q8_0 elsewhere, q4_0 nowhere; the Apex ladder keeps the highest-precision rung that fits its target context (f16, else q8_0); (b) keep today's split: q4_0 for gpt-oss-120b and its abliterated twin, an Apex ladder descending to a q4_0 target; (c) q8_0 everywhere. | E33: (a), approved before Day 1 with GLM's KV type provisional until T-04. | F33: q8_0 K and V is task-lossless (mean KLD 0.0018, at most 4 of 500 ARC answers changed); q4_0 on K collapsed Qwen2.5-7B from 92.0% to 24.2% on ARC, and gpt-oss-20b fell from 37.9% to 21.7% on AIME25 with a q4_0 cache even with Hadamard rotation, which MLA models such as V4 do not get (#21038). GLM at 8 x 32K in f16 needs about 4.8 GiB; GLM on Vulkan may need -fa off, which rules out a quantised cache for it. q4_0 was chosen only for co-residency headroom. | G33: Before Day 1 | H33: D-01; D-11; T-04; T-05 | I33: Roster report L21, L68, Addendum L136. Arsenal report what changed L88; Arsenal CR G2. FRAMEWORK_REVIEW 4.3 L264-L270, App B L1244; engines.json L25, L57, L147-L148.
A34: D-30 | B34: Reasoning mode per seat | C34: Which thinking or reasoning-effort setting does each LLM seat run (MiMo uncensored, GLM-5.3-Flash, DeepSeek-V4-Flash, Flash-Next, gpt-oss-120b), given that the research's quality and refusal figures depend on it? | D34: (a) each engine's vendor default, recorded in engines.json with its sampling; (b) a fixed setting per seat chosen after the refusal and KLD tests; (c) chosen per task tier by the router. | E34: Derived, no source recommends a setting: (b), recorded with the vendor sampling in each engines.json entry (S-19). Measure MiMo uncensored with thinking off and on in T-10 before fixing Valerie's mode. | F34: MiMo uncensored complies 99.69% with thinking off but 90.94% with thinking on; the stock DeepSeek-V4 UGI figure is with reasoning off; gpt-oss-120b's GPQA 80.1 is at high effort; Qwen3-Coder-Next is non-thinking only. S-19 names vendor sampling but no row decides the mode. | G34: Before Day 1 | H34: D-10; T-10 | I34: Arsenal report uncensored L82; Arsenal CR G4 (L113, L124), section 2 (L28). Roster report L82.
A35: D-31 | B35: Arbiter footprint units | C35: Should the Arbiter budget each engine from its exact file size in GiB instead of reading the decimal GB figure as GiB? | D35: (a) exact bytes from the Hugging Face tree (already read into MANIFEST.json at pull time) converted to GiB; (b) keep reading footprint_gb as GiB; (c) a hand-typed footprint_gib field per engine. | E35: (a). | F35: config.py reads footprint_gb as GiB, a deliberate 7.4% over-estimate: harmless at 63-130 GB files, binding at 150-158 GiB (about 11 GiB at 150 GiB, more than the cache margin of the large seats). MiMo (168.42 GB) and Flash-Next UD-Q6_K_XL (169.17 GB) would be projected at 168-169 GiB and refused against ~164 GiB, and V4-Flash UD-Q8_K_XL (161.87 GB) would keep about 2 GiB where it has about 13. | G35: Before Day 1 | H35: D-10 | I35: config.py L322-L331; FRAMEWORK_REVIEW 5.1 L317. Roster report L86; Roster baseline notes L149. Arsenal report allocation table.
A36: D-32 | B36: Residency under sequential operation | C36: Does the Arbiter allow exactly one LLM seat resident at a time, or keep two-engine residency where a pair happens to fit? | D36: (a) one weight-bearing LLM seat resident, the always-resident companions excluded; (b) keep MAX_RESIDENT = 2 for pairs that fit (for example gpt-oss-120b at 59 GiB beside Qwen3-Coder-Next Q8_0 at 79 GiB) and run the 300B-class seats exclusive. | E36: (a), with the residency limit made a setting so (b) can return without a code change. | F36: The directive is that every engine runs alone with the whole ~164 GiB. Every primary seat is 146-157 GiB, so a pair could form only between the two smaller utility engines, and keeping C26 would keep a V21 test and co-resident profile code for a case the map barely uses. | G36: Before Day 1 | H36: D-10 | I36: arbiter.py L11, L123, L916-L940; FRAMEWORK_REVIEW 4.2 rule 3 L252, C26 L999.
A37: D-33 | B37: Phase 3 decode gate | C37: How does V10 judge decode speed for engines whose bands are only projections, and which engine failures may defer without blocking the Phase 3 gate? | D37: (a) keep the fail below each band's lower bound, with bands re-based on the research projections; (b) gate on load, KV proof, generation and memory release, record decode against the projection, and fail only below a per-seat floor the Principal sets; (c) (b) plus a deferrable V22-style row for every post-pin architecture (GLM glm5-next, MiMo, Flash-Next). | E37: (c), with the per-seat floors set alongside the deep-tier floor (D-47). | F37: No candidate has a decode figure on the PRO 495 at any pin (GLM 12-14 projected from 17.4 at 3.84 bpw; V4-Flash UD-Q8_K_XL about 7 as a floor; Intern-S1 10-13; Baichuan-M3 8-13). The Apex band of 25-32 tok/s has no measurement behind it (only 2-3-bit runs exist, all on 128 GB Ryzen AI Max+ 395 boxes, none on the PRO 495: UD-IQ2_XXS 12.6-13.3 on stock Vulkan and 18.9 on a fork; UD-IQ3_XXS 11.9 on mainline b10488 and 18.4 on a fork), so a quality-first file would fail V10 on speed alone. R19 lets only the Apex (V22) defer today. | G37: Before Day 1 | H37: D-01; D-47 | I37: phase3-models.sh L33, L755; loadtest.py L238-L242; FRAMEWORK_REVIEW V10 L1074, V22 L1086, R19 L1039. Roster report L54; Roster gap_closure L354. Arsenal baseline item (gate policy).
A38: D-34 | B38: Licences: the rest | C38: Accept and record the remaining licences the research verified, now or with each engine? | D38: (a) accept all now and record them in Section 16.5 and engines.json; (b) accept each with its engine as it is approved. | E38: (b). Items: DeepSeek V4-Flash MIT; MiMo MIT; Ling-3.0-flash-Fin MIT; Derestricted gpt-oss Apache 2.0; Baichuan-M3 and Intern-S1 Apache 2.0; Qwen3-Coder-Next Apache 2.0 on its card only (LICENSE file missing); pyannote community-1 CC-BY-4.0 (gated); HiDream-I1's Llama 3.1 text encoder. Flash-Next, Nemotron and OpenMDW are D-03 to D-05; the MRL rejection is D-06. | F38: Verified on 2026-10-14 and 2026-10-15, while engines.json still marks Nemotron and DeepSeek unverified; MedGemma's HAI-DEF gate falls away if MedGemma is dropped (D-15). | G38: Before Day 1 | H38: D-03; D-04; D-05; D-06 | I38: Roster report Addendum L130; Roster gap_closure L403-L413. Arsenal report Inputs L98, verdict table.
A39: D-35 | B39: Licences: engines and companions not listed in D-34 | C39: Accept and record the licences of the engines and companions the register recommends but D-34 does not name, including the main engine GLM-5.3-Flash? | D39: (a) fold them into D-34 and accept each with its engine as it is approved; (b) accept all now and record them in 16.5 and engines.json. | E39: (a). Items: GLM-5.3-Flash MIT (the arsenal's main engine); Qwen3-Embedding-8B/4B and Qwen3-Reranker-8B/4B Apache 2.0; Qwen3-VL-235B Apache 2.0 (vision runner-up); OCR candidates TeleOCR, OvisOCR2 and PaddleOCR-VL-1.6 Apache 2.0, GLM-OCR MIT; Qwen3-ASR-1.7B and Qwen3-TTS Apache 2.0; Chatterbox Turbo and Multilingual V3 MIT; Z-Image-Turbo and Qwen-Image-2512 Apache 2.0; EmbeddingGemma 2 Apache 2.0 if kept (D-60). | F39: D-34 lists DeepSeek, MiMo, Ling, Derestricted, Baichuan-M3, Intern-S1, Coder-Next, pyannote community-1 and HiDream only, so the licence of the engine that carries most seats, and every new companion, has no acceptance row; S-27 and S-45 record licences only for what a decision accepts. | G39: Before Day 1 | H39: D-34 | I39: Arsenal report Inputs L98 (GLM, DeepSeek, MiMo MIT), verdict row 11 (L52). Arsenal CR section 2 (L35, EG2 Apache 2.0), G8 (L184-L188). Roster report Addendum L130.
A40: D-36 | B40: Kernel GTT line | C40: Keep the GTT and TTM kernel line as written for 192 GB, or change it before Day 1? | D40: (a) keep amdgpu.gttsize=196608 ttm.pages_limit=50331648 and let V3 and V3b validate it; (b) adopt the one published 192 GB profile, ttm.pages_limit=46137344 (176 GiB); (c) keep (a) and raise the V3b floor from 160000 MiB to the largest approved engine plus its KV. | E40: (c). | F40: No community source has qualified a 192 GB GTT profile, and AMD's footnote caps graphics memory at 160 GB (149.01 GiB). The Lucebox report, which governs hardware, finds the node's line already covers its 192 GB profile (amdgpu.gttsize=180224, about 146.5 GiB of experts in GTT). The largest candidates are 146-158 GiB files, so a Vulkan heap below about 165 GiB would shut them out. | G40: Before Day 1 | H40: T-01 | I40: Roster report L114, Addendum L138; Roster gap_closure L359, L467; FRAMEWORK_REVIEW 3.3 L123-L135. Lucebox report tier table L186, L331.
A41: D-37 | B41: Specialist seats: how they are reached | C41: Are the new specialist engines (science, finance, coder, medical cross-check) bound to directors and task forces, or to domains, and do they get Principal prefixes? | D41: (a) director override lists plus task-force presets (an engine field in task-forces.json), keeping 8.4's rule that a domain never spawns a model; (b) a domain card carries an engine and loading the card switches the engine; (c) (a) plus explicit prefixes such as [SCIENCE], [CODER] and [FIN]. | E41: (a), adding a prefix only for a seat the Principal wants to call directly. | F41: Domains are knowledge injected into the director's prompt (8.4), and every extra engine is now a 50-85 s swap plus re-prefill, so binding engines to cards could turn one three-card dispatch into three swaps. Persona files already carry default_engine and override_engines, and task-forces.json already carries an engine field for TF_OMEGA. | G41: Before Day 1 | H41: D-17; D-18; D-19; D-15 | I41: FRAMEWORK_REVIEW 8.4 L527-L535, 8.5 L539-L553; config/personas/*.md L7-L11; config/task-forces.json L358.
...

Sheet 2 Named models
A1: Named models
A2: The twelve models and engines the Principal named, with the recommended verdict. Accept the verdict or state a change.
A4: ID | B4: Named model | C4: Recommended verdict | D4: Rung that fits alone | E4: Size (GB / GiB) | F4: Role in the arsenal | G4: Reason and evidence | H4: Source | I4: Your response | J4: Your choice or alternative | K4: Your comments
A5: N-01 | B5: DeepSeek-V4-Flash | C5: Include | D5: UD-Q8_K_XL (bit-exact), unsloth/DeepSeek-V4-Flash-0731-GGUF | E5: 161.87 GB / 150.75 GiB | F5: Apex / TF_OMEGA, Arthur, Deep Think adversary; reasoning and long context | G5: The only named engine with a lossless fitting rung (bit-identical to the official weights on all 1,328 tensors; KLD about 0, 100% top-1), inside the pin, MIT; AA 34.3, CritPt 16.6 lead, HLE 38.6, GPQA 90.8; the dsv4 KV (about 6,880 B/token) lets a 1M context fit. 0731 ships no MTP head (DSpark only). V4.1-Flash (552B) is a different model, governed by the Lucebox report as an evaluation-only trial (D-46); every fitting V4.1 file is 2-3 bit (KL about 0.26). huihui's abliterated 0731 is excluded (experts not ablated, 4-bit only). | H5: Arsenal report verdict row 1 (L42); verification_named_heavyweight_moe row 4. Roster report L68, L86, L110, Addendum L126-L136. Lucebox report Inputs rows 1-2 (L392-393).
A6: N-02 | B6: Qwen3-235B-A22B | C6: Exclude | D6: Q5_K_S (about 5.5 bpw), or Q4_K_M for long context | E6: 161.88 GB / 150.76 GiB | F6: None; its post-trains Intern-S1 (science) and Baichuan-M3 (medical) take seats | G6: Superseded: a 2025 model at AA 12.7, far below the 2026 leaders, and its 188 KiB/token KV caps the 5-bit rung near 23K context after buffers. | H6: Arsenal report verdict row 2 (L43); verification_named_heavyweight_moe row 13.
A7: N-03 | B7: GLM-5.3-Flash 320B | C7: Include with conditions | D7: UD-IQ4_XS (KLD 0.117, 88.2% top-1, lossy) | E7: 156.82 GB / 146.05 GiB | F7: General quality lead: Ren, Gideon, Silas, Helena, Victor, Minerva primary; vision (glm5v); long documents; Deep Think generator | G7: Conditions: re-pin to b11279 / v0.6.0 or later (D-01) and the KLD run (T-03). AA 41.8, top in-envelope; MIT; leads most legal, finance, medical, agentic and long-context boards but fits only at about 4 bits. KV 19,712 B/token f16 with the DSA indexer, about 469K context after a 9 GiB allowance. The roster research rejected it as 3-bit only (UD-Q3_K_XL 147.54 GB) with a Vulkan CPU fallback for its hyper-connection op and --kv-unified needed; those cautions become T-04. | H7: Arsenal report verdict row 3 (L44); Arsenal CR G1, G2. Roster report L35, L56, L86; Roster gap_closure L385.
A8: N-04 | B8: Qwen3-Coder-Next | C8: Include with conditions | D8: Q8_0 (practical); BF16 also fits | E8: Q8_0 84.81 GB / 78.99 GiB; BF16 159.46 GB / 148.51 GiB | F8: Dedicated coder, only if the Principal wants one (D-19) | G8: Just above the 70B floor (79.7B total, 3B active), inside the pin; the only named engine whose full BF16 fits with 256K context, but BF16 decode is kernel-limited (about 9 tok/s projected on Vulkan) against 37-44 projected at Q8_0; neither rung has a gfx1151 llama.cpp measurement. Vendor SWE-bench Verified 70.6-71.3, Aider 66.2; AA 9.24; GLM beats it on SWE-bench (Vals). Apache 2.0 rests on the card (LICENSE file missing). | H8: Arsenal report verdict row 4 (L45); verification_quantization_value row 19. Roster report L70, L90; Roster gap_closure L61-L63, L412.
A9: N-05 | B9: Llama 4 Maverick | C9: Exclude | D9: 2-3 bit only: UD-Q2_K_XL or i1-IQ3_XS | E9: UD-Q2_K_XL 152.66 GB / 142.17 GiB; i1-IQ3_XS 163.35 GB / 152.13 GiB | F9: None | G9: No KLD at any fitting rung and near the bottom of every current board (AA 9.3; LMArena #260 of 415); only 2-3 bit rungs fit, which the less-quantisation rule rejects (D-24). Vision works at the pin, but the model is out-classed. | H9: Arsenal report verdict row 5 (L46); verification_named_heavyweight_moe row 17.
A10: N-06 | B10: Mistral Large 2 Uncensored | C10: Exclude | D10: Q4_0 (the named Ollama build) | E10: 69.08 GB / 64.34 GiB | F10: None (D-06) | G10: gdisney/mistral-large-uncensored is stock Mistral-Large-2407 at legacy Q4_0 plus a system prompt instructing misinformation, under the research and non-commercial MRL licence. The weight-edited alternative is XORTRON (2411 Heretic) Q8_0 130.28 GB / 121.33 GiB, a dense 123B at about 1.7 tok/s. | H10: Arsenal report verdict row 6 (L47); verification_named_120b_class_and_uncensored L52.
A11: N-07 | B11: Qwen3.8 Flash-Next | C11: Include | D11: UD-Q6_K_XL (KLD 0.0271, matches its own Q8_0) | E11: 169.17 GB / 157.55 GiB | F11: Corporate challenger; runner-up for Ren and Victor; science QA; coding; vision; Deep Think third opinion | G11: Re-pin advised (b11330 or later): it loads at the pin, but its Vulkan hyper-connection ops (#28988), MTP (#29761) and the #29751 attention fix are later (measured only at UD-IQ4_XS on 128 GB Ryzen AI Max+ 395 boxes: 26.9-27.2 tok/s without MTP (the roster infers v0.4.1 gets this) and 41.3 with MTP on PR #28243 fork builds; nothing is measured at UD-Q6_K_XL (23-29 tok/s projected)). AA 39.8 (second of the twelve), GPQA 92.3, Terminal-Bench 2.1 86.1 (top open); Qwen Community 1.0, internal use exempt (D-03). About 6.5 GiB left, so companion growth can push it to UD-Q5_K_XL (D-28). Its huihui v2 (unsloth-recipe UD-Q6_K_XL 157.55 GiB, experts not ablated) and cygnal Heretic2 (IQ4_XS) abliterations are excluded: neither publishes refusal or quality data. | H11: Arsenal report verdict row 7 (L48); verification_named_heavyweight_moe row 19. Roster report L66, L82, L110, Addendum L126-L136; Roster gap_closure L373-L374, L400.
A12: N-08 | B12: Nemotron 3 Super Q8 | C12: Include | D12: Q8_0 (release precision), 4 shards | E12: 128.47 GB / 119.65 GiB | F12: Long-context utility; long-document runner-up; Estate option, no longer Arthur's default (D-13) | G12: Fits with about 44 GiB spare and a 1M-token context at tiny KV, inside the pin, but AA 12.8 and its card discloses an HLE/GPQA contamination risk; no MTP at the pin. The Vulkan fault near 20K-token prompts (#20732) was closed with no fix (T-12). Licence read (D-04); an optional Heretic build exists (D-58). | H12: Arsenal report verdict row 8 (L49); verification_quantization_value L28. Roster report L67, L84; Roster gap_closure L380, L418, L437.
A13: N-09 | B13: gpt-oss-120b | C13: Include | D13: MXFP4 (release precision); F16-trunk is the highest-precision GGUF (D-59) | E13: MXFP4 63.39 GB / 59.03 GiB; F16-trunk 65.37 GB / 60.88 GiB | F13: Fast utility, drafting, Sentinel escalation; fallback floor for every seat (D-40) | G13: Native MXFP4 experts make it lossless at release precision, and it is the fastest engine: 57-60 tok/s projected by the arsenal, 53.8-55.6 measured on 128 GB boxes (roster). AA 11.6 makes it a speed engine, not a quality seat, now that co-residency no longer rewards its size (D-12). | H13: Arsenal report verdict row 9 (L50); verification_quantization_value row 22. Roster report L66, L82, Addendum L128, L134.
A14: N-10 | B14: gpt-oss-120b Abliterated | C14: Include with conditions | D14: ArliAI Derestricted Q8_0 (or Derestricted MXFP4_MOE) | E14: Q8_0 124.30 GB / 115.76 GiB; MXFP4_MOE 63.39 GB / 59.03 GiB | F14: Explicit-override uncensored seat for Ren and Arthur; Valerie fallback | G14: Condition: the Derestricted build, not the node's current file. The current huihui v2 -> noctrex MXFP4_MOE has no provenance card or data and huihui's repos return 401 (retire, D-09); kldzj Heretic v2 measures KL 0.53 with 22/100 refusals. Derestricted is the best measured variant (UGI NatInt 35.70 vs base 33.68), Apache 2.0, and its Q8_0 keeps the edited experts near BF16. | H14: Arsenal report verdict row 10 (L51); Arsenal CR G4 (L118-122). Roster report L80, L108; Roster gap_closure L349, L393, L455.
A15: N-11 | B15: EmbeddingGemma 2 | C15: Include with conditions | D15: Q8_0 or BF16 | E15: Q8_0 0.31 GB / 0.29 GiB; BF16 0.56 GB / 0.52 GiB | F15: Optional multimodal and code side index, not the primary embedder (D-60) | G15: Condition: side index only, after a re-pin to b11452 or later (b11474 covers it, v0.6.0 does not). MTEB multilingual 61.36 (+0.21 over EG1), English -1.21, 9-13 points below the 8B-27B leaders; its value is one shared space for text, image, video and audio plus code retrieval (+9.92). | H15: Arsenal report verdict row 11 (L52); verification_named_companion_engines rows 4-6.
A16: N-12 | B16: Nemotron 3 Diarization | C16: Include | D16: Official Q8_0 GGUF (NeMo-Speech.cpp format, not llama.cpp) | E16: 0.11 GB / 0.10 GiB | F16: Primary diariser (C-06) | G16: Best open result on the only same-harness comparison (OpenBench average DER 0.19 vs pyannote community-1 0.28; 0.206 vs 0.300 without the contaminated VoxConverse set); OpenMDW-1.1 (D-05); tiny memory; runs on the node's ggml/Vulkan stack. Handles up to eight speakers; community-1 stays the fallback beyond that. | H16: Arsenal report verdict row 12 (L53); verification_named_companion_engines rows 18, 23. Roster report L77, L102.

Sheet 3 Persona allocation
A1: Persona allocation
A2: Recommended engine for each persona and agent, each running alone at the least-quantised rung that fits. Projections until the node measures them.
A4: ID | B4: Persona or agent | C4: Discipline | D4: Recommended engine | E4: Rung | F4: Size (GB / GiB) | G4: Decode (basis) | H4: Strongest evidence | I4: Runner-up | J4: Source | K4: Your response | L4: Your choice or alternative | M4: Your comments
A5: P-01 | B5: Ren (Corporate lead) | C5: General, negotiation, geopolitics | D5: GLM-5.3-Flash (unsloth UD-IQ4_XS) (provisional: UD-IQ4_XS is lossy, KLD 0.117; pending the node KLD run T-03, D-02) | E5: UD-IQ4_XS | F5: 156.82 GB / 146.05 GiB | G5: 12-14 tok/s projected (17.4 measured on a PRO 495 at 3.84 bpw, Vulkan, post-pin build) | H5: AA 41.8, top in-envelope; LMArena #29 overall. KV 19,712 B/token f16, about 469K context after a 9 GiB allowance. Replaces gpt-oss-120b as Corporate default (D-12). | I5: Qwen3.8-Flash-Next UD-Q6_K_XL | J5: Arsenal report allocation L17. Roster report L66, L82.
A6: P-02 | B6: Arthur (Estate lead) | C6: General, estate, academia | D6: DeepSeek-V4-Flash-0731 (unsloth UD-Q8_K_XL) | E6: UD-Q8_K_XL | F6: 161.87 GB / 150.75 GiB | G6: About 7 tok/s on mainline Vulkan (floor; in-pin kernels unmeasured); about 11 at UD-Q4_K_XL | H6: Bit-exact, KLD about 0; AA 34.3; CritPt 16.6 lead. KV about 6,880 B/token f16, so a 1M context fits. Replaces Nemotron 3 Super as Estate default (D-13). | I6: GLM-5.3-Flash (diversity against Ren); Nemotron 3 Super Q8_0 (former default) | J6: Arsenal report allocation L18. Roster report L67, L84.
A7: P-03 | B7: Gideon (law, strata, HR) | C7: Legal, compliance | D7: GLM-5.3-Flash (provisional: UD-IQ4_XS is lossy, KLD 0.117; pending the node KLD run T-03, D-02) | E7: UD-IQ4_XS | F7: 156.82 GB / 146.05 GiB | G7: 12-14 tok/s projected | H7: LegalBench 83.93% (top open model that fits); Legal Research 45.19%. US-centric boards only; no Australian-law or HR evaluation exists (D-49). GLM Legal (86.23%) is API-only, on the watch-list. | I7: DeepSeek-V4-Flash-0731 (LegalBench 77.71%) | J7: Arsenal report allocation L19. Roster report L94.
A8: P-04 | B8: Silas (CFO, audit, fraud) | C8: Finance, tax | D8: GLM-5.3-Flash (provisional: UD-IQ4_XS is lossy, KLD 0.117; pending the node KLD run T-03, D-02) | E8: UD-IQ4_XS | F8: 156.82 GB / 146.05 GiB | G8: 12-14 tok/s projected | H8: Finance Agent v2 57.85% (top open); TaxEval 75.59%. | I8: Ling-3.0-flash-Fin Q8_0 135.63 GB / 126.32 GiB (finance-tuned, lossless; FAB v2 54.93%; D-18) | J8: Arsenal report allocation L20.
A9: P-05 | B9: Valerie (infra, DevOps, cyber; uncensored default) | C9: Cybersecurity, AEGIS | D9: MiMo-V2.6-Flash uncensored (dealignai RL-UNCENSORED, AliceThirty MXFP4) | E9: MXFP4 | F9: 168.42 GB / 156.85 GiB | G9: About 18 tok/s (stock MiMo MXFP4 measured 18.3 on a PRO 495, ROCm) | H9: Vals CyberBench 75.36% (top open); MMLU -0.14 pp against base. Fits with about 7 GiB spare. The roster research put it after the pin; the arsenal review (C6) finds the mimo2 runtime in v0.4.1, so loading at the pin is untested (T-09). | I9: gpt-oss-120b Derestricted Q8_0 (D-07 (b)) | J9: Arsenal report allocation L21; Arsenal CR C6. Roster report L38; Roster gap_closure L378.
A10: P-06 | B10: Helena (comms, PR, crisis, creative) | C10: Communications, creative | D10: GLM-5.3-Flash (provisional: UD-IQ4_XS is lossy, KLD 0.117; pending the node KLD run T-03, D-02) | E10: UD-IQ4_XS | F10: 156.82 GB / 146.05 GiB | G10: 12-14 tok/s projected | H10: LMArena creative #45 (top open); entertainment #38. No EQ-Bench result exists for GLM. | I10: DeepSeek-V4-Flash-0731 (EQ-Bench Creative Writing 1441.1; the stronger 1559.1 belongs to the April preview checkpoint, not 0731) | J10: Arsenal report allocation L22.
A11: P-07 | B11: Minerva (health, longevity) | C11: Medicine; cross-check | D11: GLM-5.3-Flash primary (provisional: UD-IQ4_XS is lossy, KLD 0.117; pending the node KLD run T-03, D-02) + Baichuan-M3-235B cross-check | E11: UD-IQ4_XS / Q5_K_S (or official Q4_K_M) | F11: 146.05 GiB; Baichuan Q5_K_S 161.88 GB / 150.76 GiB or Q4_K_M 143.78 GB / 133.91 GiB | G11: GLM 12-14 tok/s; Baichuan-M3 8-13 tok/s (projections; no gfx1151 measurement) | H11: GLM MedScribe 88.94%, MLCR 51.1 (top open); Baichuan-M3 HealthBench 65.1 / Hard 44.4 (vendor, no independent index). Baichuan's 188 KiB/token KV caps context near 23K at Q5 (D-16). Replaces Meditron-70B (D-15). | I11: Intern-S1 (science subdomains); MedGemma-27B dropped under the 70B floor | J11: Arsenal report allocation L23. Roster report L71, L96, Addendum L132, L140.
A12: P-08 | B12: Victor (aviation, transport, concierge) | C12: No domain board | D12: GLM-5.3-Flash (provisional: UD-IQ4_XS is lossy, KLD 0.117; pending the node KLD run T-03, D-02) | E12: UD-IQ4_XS | F12: 156.82 GB / 146.05 GiB | G12: 12-14 tok/s projected | H12: General leaders only (tau-Banking 47.2, GDPval-AA, AutomationBench 60.4); quality can be settled only on the Principal's own test sets (D-49). | I12: Qwen3.8-Flash-Next | J12: Arsenal report allocation L24.
A13: P-09 | B13: Alaric (OSINT, protection, Sentinel) | C13: Physical security, OSINT | D13: MiMo-V2.6-Flash uncensored (shared with Valerie) | E13: MXFP4 | F13: 168.42 GB / 156.85 GiB | G13: About 18 tok/s (stock MiMo MXFP4 measured, PRO 495, ROCm) | H13: No OSINT or physical-security board; cyber lead plus generalist strength. | I13: GLM-5.3-Flash | J13: Arsenal report allocation L25.
A14: P-10 | B14: Eleanor (router, dispatch, logistics) | C14: Classification, routing, LightRAG extraction | D14: Qwen3.5-4B (resident companion) | E14: Q8_0 | F14: 4.5 GB / 4.19 GiB | G14: Fast; always resident, thinking off (no measured figure) | H14: A companion, outside the no-small-models rule; the only 4B-class model with a 2026 date and llama.cpp text and vision; Qwen 3.8 shipped no small model (G8). | I14: Gemma 4 E4B; Granite 4.1 8B (no measured routing advantage) | J14: Arsenal report allocation L26. Roster report L74, L100.
A15: P-11 | B15: Deep Think generator / adversary | C15: Cross-model reasoning | D15: GLM-5.3-Flash + DeepSeek-V4-Flash-0731 (two families) | E15: UD-IQ4_XS / UD-Q8_K_XL | F15: 146.05 GiB; 150.75 GiB | G15: As each engine, run in turn at about 50-85 s per swap plus re-prefill | H15: AA HLE 39.9 / 38.6; GPQA 91.2 / 90.8 (D-22). | I15: Qwen3.8-Flash-Next (third opinion) | J15: Arsenal report allocation L27.
